Workbook

Sheet tgr_fd68e454.base_table_assignm
A1: Tabel | B1: Kolom | C1: DataKey | D1: Urutan | E1: Blok | F1: Nomor Rincian | G1: Label | H1: Tipe | I1: Keterangan
A2: tgr_fd68e454.base_table_assignment | B2: email | C2: email | D2: =IFERROR(VLOOKUP($C2,'_METADATA_TEMPLATE'!$B$2:$H$826,2,FALSE),"") -> 131 | E2: =IFERROR(VLOOKUP($C2,'_METADATA_TEMPLATE'!$B$2:$H$826,4,FALSE),"") -> SE2026 - L BLOK II | F2: =IFERROR(VLOOKUP($C2,'_METADATA_TEMPLATE'!$B$2:$H$826,5,FALSE),"") | G2: =IFERROR(VLOOKUP($C2,'_METADATA_TEMPLATE'!$B$2:$H$826,6,FALSE),"") -> • Email | H2: =IFERROR(VLOOKUP($C2,'_METADATA_TEMPLATE'!$B$2:$H$826,7,FALSE),"") -> Text Input | I2: =IFERROR(VLOOKUP(C2,'_METADATA_DEFAULT'!$A:$B,2,FALSE),"")
A3: tgr_fd68e454.base_table_assignment | B3: mode | C3: mode | D3: =IFERROR(VLOOKUP($C3,'_METADATA_TEMPLATE'!$B$2:$H$826,2,FALSE),"") -> 483 | E3: =IFERROR(VLOOKUP($C3,'_METADATA_TEMPLATE'!$B$2:$H$826,4,FALSE),"") | F3: =IFERROR(VLOOKUP($C3,'_METADATA_TEMPLATE'!$B$2:$H$826,5,FALSE),"") | G3: =IFERROR(VLOOKUP($C3,'_METADATA_TEMPLATE'!$B$2:$H$826,6,FALSE),"") -> Mode | H3: =IFERROR(VLOOKUP($C3,'_METADATA_TEMPLATE'!$B$2:$H$826,7,FALSE),"") -> Variable | I3: =IFERROR(VLOOKUP(C3,'_METADATA_DEFAULT'!$A:$B,2,FALSE),"") -> Moda Survei
A4: tgr_fd68e454.base_table_assignment | B4: assignment_id | C4: assignment_id | D4: =IFERROR(VLOOKUP($C4,'_METADATA_TEMPLATE'!$B$2:$H$826,2,FALSE),"") | E4: =IFERROR(VLOOKUP($C4,'_METADATA_TEMPLATE'!$B$2:$H$826,4,FALSE),"") | F4: =IFERROR(VLOOKUP($C4,'_METADATA_TEMPLATE'!$B$2:$H$826,5,FALSE),"") | G4: =IFERROR(VLOOKUP($C4,'_METADATA_TEMPLATE'!$B$2:$H$826,6,FALSE),"") | H4: =IFERROR(VLOOKUP($C4,'_METADATA_TEMPLATE'!$B$2:$H$826,7,FALSE),"") | I4: =IFERROR(VLOOKUP(C4,'_METADATA_DEFAULT'!$A:$B,2,FALSE),"") -> ID Assignment
A5: tgr_fd68e454.base_table_assignment | B5: level_1_full_code | C5: level_1_full_code | D5: =IFERROR(VLOOKUP($C5,'_METADATA_TEMPLATE'!$B$2:$H$826,2,FALSE),"") | E5: =IFERROR(VLOOKUP($C5,'_METADATA_TEMPLATE'!$B$2:$H$826,4,FALSE),"") | F5: =IFERROR(VLOOKUP($C5,'_METADATA_TEMPLATE'!$B$2:$H$826,5,FALSE),"") | G5: =IFERROR(VLOOKUP($C5,'_METADATA_TEMPLATE'!$B$2:$H$826,6,FALSE),"") | H5: =IFERROR(VLOOKUP($C5,'_METADATA_TEMPLATE'!$B$2:$H$826,7,FALSE),"") | I5: =IFERROR(VLOOKUP(C5,'_METADATA_DEFAULT'!$A:$B,2,FALSE),"") -> Kode Lengkap Provinsi
A6: tgr_fd68e454.base_table_assignment | B6: level_2_full_code | C6: level_2_full_code | D6: =IFERROR(VLOOKUP($C6,'_METADATA_TEMPLATE'!$B$2:$H$826,2,FALSE),"") | E6: =IFERROR(VLOOKUP($C6,'_METADATA_TEMPLATE'!$B$2:$H$826,4,FALSE),"") | F6: =IFERROR(VLOOKUP($C6,'_METADATA_TEMPLATE'!$B$2:$H$826,5,FALSE),"") | G6: =IFERROR(VLOOKUP($C6,'_METADATA_TEMPLATE'!$B$2:$H$826,6,FALSE),"") | H6: =IFERROR(VLOOKUP($C6,'_METADATA_TEMPLATE'!$B$2:$H$826,7,FALSE),"") | I6: =IFERROR(VLOOKUP(C6,'_METADATA_DEFAULT'!$A:$B,2,FALSE),"") -> Kode Lengkap Kabupaten/Kota
A7: tgr_fd68e454.base_table_assignment | B7: is_active | C7: is_active | D7: =IFERROR(VLOOKUP($C7,'_METADATA_TEMPLATE'!$B$2:$H$826,2,FALSE),"") | E7: =IFERROR(VLOOKUP($C7,'_METADATA_TEMPLATE'!$B$2:$H$826,4,FALSE),"") | F7: =IFERROR(VLOOKUP($C7,'_METADATA_TEMPLATE'!$B$2:$H$826,5,FALSE),"") | G7: =IFERROR(VLOOKUP($C7,'_METADATA_TEMPLATE'!$B$2:$H$826,6,FALSE),"") | H7: =IFERROR(VLOOKUP($C7,'_METADATA_TEMPLATE'!$B$2:$H$826,7,FALSE),"") | I7: =IFERROR(VLOOKUP(C7,'_METADATA_DEFAULT'!$A:$B,2,FALSE),"") -> 1 = Aktif, 0 = Dihapus
A8: tgr_fd68e454.base_table_assignment | B8: approved_by_creator | C8: approved_by_creator | D8: =IFERROR(VLOOKUP($C8,'_METADATA_TEMPLATE'!$B$2:$H$826,2,FALSE),"") | E8: =IFERROR(VLOOKUP($C8,'_METADATA_TEMPLATE'!$B$2:$H$826,4,FALSE),"") | F8: =IFERROR(VLOOKUP($C8,'_METADATA_TEMPLATE'!$B$2:$H$826,5,FALSE),"") | G8: =IFERROR(VLOOKUP($C8,'_METADATA_TEMPLATE'!$B$2:$H$826,6,FALSE),"") | H8: =IFERROR(VLOOKUP($C8,'_METADATA_TEMPLATE'!$B$2:$H$826,7,FALSE),"") | I8: =IFERROR(VLOOKUP(C8,'_METADATA_DEFAULT'!$A:$B,2,FALSE),"")
A9: tgr_fd68e454.base_table_assignment | B9: assignment_error_status_type | C9: assignment_error_status_type | D9: =IFERROR(VLOOKUP($C9,'_METADATA_TEMPLATE'!$B$2:$H$826,2,FALSE),"") | E9: =IFERROR(VLOOKUP($C9,'_METADATA_TEMPLATE'!$B$2:$H$826,4,FALSE),"") | F9: =IFERROR(VLOOKUP($C9,'_METADATA_TEMPLATE'!$B$2:$H$826,5,FALSE),"") | G9: =IFERROR(VLOOKUP($C9,'_METADATA_TEMPLATE'!$B$2:$H$826,6,FALSE),"") | H9: =IFERROR(VLOOKUP($C9,'_METADATA_TEMPLATE'!$B$2:$H$826,7,FALSE),"") | I9: =IFERROR(VLOOKUP(C9,'_METADATA_DEFAULT'!$A:$B,2,FALSE),"")
A10: tgr_fd68e454.base_table_assignment | B10: assignment_id_timestamp | C10: assignment_id_timestamp | D10: =IFERROR(VLOOKUP($C10,'_METADATA_TEMPLATE'!$B$2:$H$826,2,FALSE),"") | E10: =IFERROR(VLOOKUP($C10,'_METADATA_TEMPLATE'!$B$2:$H$826,4,FALSE),"") | F10: =IFERROR(VLOOKUP($C10,'_METADATA_TEMPLATE'!$B$2:$H$826,5,FALSE),"") | G10: =IFERROR(VLOOKUP($C10,'_METADATA_TEMPLATE'!$B$2:$H$826,6,FALSE),"") | H10: =IFERROR(VLOOKUP($C10,'_METADATA_TEMPLATE'!$B$2:$H$826,7,FALSE),"") | I10: =IFERROR(VLOOKUP(C10,'_METADATA_DEFAULT'!$A:$B,2,FALSE),"") -> ID Assignment + Timestamp
A11: tgr_fd68e454.base_table_assignment | B11: assignment_responsibility_admin | C11: assignment_responsibility_admin | D11: =IFERROR(VLOOKUP($C11,'_METADATA_TEMPLATE'!$B$2:$H$826,2,FALSE),"") | E11: =IFERROR(VLOOKUP($C11,'_METADATA_TEMPLATE'!$B$2:$H$826,4,FALSE),"") | F11: =IFERROR(VLOOKUP($C11,'_METADATA_TEMPLATE'!$B$2:$H$826,5,FALSE),"") | G11: =IFERROR(VLOOKUP($C11,'_METADATA_TEMPLATE'!$B$2:$H$826,6,FALSE),"") | H11: =IFERROR(VLOOKUP($C11,'_METADATA_TEMPLATE'!$B$2:$H$826,7,FALSE),"") | I11: =IFERROR(VLOOKUP(C11,'_METADATA_DEFAULT'!$A:$B,2,FALSE),"")
A12: tgr_fd68e454.base_table_assignment | B12: assignment_status_alias | C12: assignment_status_alias | D12: =IFERROR(VLOOKUP($C12,'_METADATA_TEMPLATE'!$B$2:$H$826,2,FALSE),"") | E12: =IFERROR(VLOOKUP($C12,'_METADATA_TEMPLATE'!$B$2:$H$826,4,FALSE),"") | F12: =IFERROR(VLOOKUP($C12,'_METADATA_TEMPLATE'!$B$2:$H$826,5,FALSE),"") | G12: =IFERROR(VLOOKUP($C12,'_METADATA_TEMPLATE'!$B$2:$H$826,6,FALSE),"") | H12: =IFERROR(VLOOKUP($C12,'_METADATA_TEMPLATE'!$B$2:$H$826,7,FALSE),"") | I12: =IFERROR(VLOOKUP(C12,'_METADATA_DEFAULT'!$A:$B,2,FALSE),"") -> Status Assignment
A13: tgr_fd68e454.base_table_assignment | B13: assignment_status_id | C13: assignment_status_id | D13: =IFERROR(VLOOKUP($C13,'_METADATA_TEMPLATE'!$B$2:$H$826,2,FALSE),"") | E13: =IFERROR(VLOOKUP($C13,'_METADATA_TEMPLATE'!$B$2:$H$826,4,FALSE),"") | F13: =IFERROR(VLOOKUP($C13,'_METADATA_TEMPLATE'!$B$2:$H$826,5,FALSE),"") | G13: =IFERROR(VLOOKUP($C13,'_METADATA_TEMPLATE'!$B$2:$H$826,6,FALSE),"") | H13: =IFERROR(VLOOKUP($C13,'_METADATA_TEMPLATE'!$B$2:$H$826,7,FALSE),"") | I13: =IFERROR(VLOOKUP(C13,'_METADATA_DEFAULT'!$A:$B,2,FALSE),"") -> ID Status Assignment
... A83: tgr_fd68e454.base_table_assignment | B83: assignment_date_modified | C83: assignment_date_modified | D83: =IFERROR(VLOOKUP($C83,'_METADATA_TEMPLATE'!$B$2:$H$826,2,FALSE),"") | E83: =IFERROR(VLOOKUP($C83,'_METADATA_TEMPLATE'!$B$2:$H$826,4,FALSE),"") | F83: =IFERROR(VLOOKUP($C83,'_METADATA_TEMPLATE'!$B$2:$H$826,5,FALSE),"") | G83: =IFERROR(VLOOKUP($C83,'_METADATA_TEMPLATE'!$B$2:$H$826,6,FALSE),"") | H83: =IFERROR(VLOOKUP($C83,'_METADATA_TEMPLATE'!$B$2:$H$826,7,FALSE),"") | I83: =IFERROR(VLOOKUP(C83,'_METADATA_DEFAULT'!$A:$B,2,FALSE),"") -> Tanggal Assignment Terakhir Diubah

Sheet tgr_fd68e454.base_table_assig_1
A1: Tabel | B1: Kolom | C1: DataKey | D1: Urutan | E1: Blok | F1: Nomor Rincian | G1: Label | H1: Tipe | I1: Keterangan
A2: tgr_fd68e454.base_table_assignment_history | B2: mode | C2: mode | D2: =IFERROR(VLOOKUP($C2,'_METADATA_TEMPLATE'!$B$2:$H$826,2,FALSE),"") -> 483 | E2: =IFERROR(VLOOKUP($C2,'_METADATA_TEMPLATE'!$B$2:$H$826,4,FALSE),"") | F2: =IFERROR(VLOOKUP($C2,'_METADATA_TEMPLATE'!$B$2:$H$826,5,FALSE),"") | G2: =IFERROR(VLOOKUP($C2,'_METADATA_TEMPLATE'!$B$2:$H$826,6,FALSE),"") -> Mode | H2: =IFERROR(VLOOKUP($C2,'_METADATA_TEMPLATE'!$B$2:$H$826,7,FALSE),"") -> Variable | I2: =IFERROR(VLOOKUP(C2,'_METADATA_DEFAULT'!$A:$B,2,FALSE),"") -> Moda Survei
A3: tgr_fd68e454.base_table_assignment_history | B3: assignment_id | C3: assignment_id | D3: =IFERROR(VLOOKUP($C3,'_METADATA_TEMPLATE'!$B$2:$H$826,2,FALSE),"") | E3: =IFERROR(VLOOKUP($C3,'_METADATA_TEMPLATE'!$B$2:$H$826,4,FALSE),"") | F3: =IFERROR(VLOOKUP($C3,'_METADATA_TEMPLATE'!$B$2:$H$826,5,FALSE),"") | G3: =IFERROR(VLOOKUP($C3,'_METADATA_TEMPLATE'!$B$2:$H$826,6,FALSE),"") | H3: =IFERROR(VLOOKUP($C3,'_METADATA_TEMPLATE'!$B$2:$H$826,7,FALSE),"") | I3: =IFERROR(VLOOKUP(C3,'_METADATA_DEFAULT'!$A:$B,2,FALSE),"") -> ID Assignment
A4: tgr_fd68e454.base_table_assignment_history | B4: date_created | C4: date_created | D4: =IFERROR(VLOOKUP($C4,'_METADATA_TEMPLATE'!$B$2:$H$826,2,FALSE),"") | E4: =IFERROR(VLOOKUP($C4,'_METADATA_TEMPLATE'!$B$2:$H$826,4,FALSE),"") | F4: =IFERROR(VLOOKUP($C4,'_METADATA_TEMPLATE'!$B$2:$H$826,5,FALSE),"") | G4: =IFERROR(VLOOKUP($C4,'_METADATA_TEMPLATE'!$B$2:$H$826,6,FALSE),"") | H4: =IFERROR(VLOOKUP($C4,'_METADATA_TEMPLATE'!$B$2:$H$826,7,FALSE),"") | I4: =IFERROR(VLOOKUP(C4,'_METADATA_DEFAULT'!$A:$B,2,FALSE),"")
A5: tgr_fd68e454.base_table_assignment_history | B5: level_1_full_code | C5: level_1_full_code | D5: =IFERROR(VLOOKUP($C5,'_METADATA_TEMPLATE'!$B$2:$H$826,2,FALSE),"") | E5: =IFERROR(VLOOKUP($C5,'_METADATA_TEMPLATE'!$B$2:$H$826,4,FALSE),"") | F5: =IFERROR(VLOOKUP($C5,'_METADATA_TEMPLATE'!$B$2:$H$826,5,FALSE),"") | G5: =IFERROR(VLOOKUP($C5,'_METADATA_TEMPLATE'!$B$2:$H$826,6,FALSE),"") | H5: =IFERROR(VLOOKUP($C5,'_METADATA_TEMPLATE'!$B$2:$H$826,7,FALSE),"") | I5: =IFERROR(VLOOKUP(C5,'_METADATA_DEFAULT'!$A:$B,2,FALSE),"") -> Kode Lengkap Provinsi
A6: tgr_fd68e454.base_table_assignment_history | B6: level_2_full_code | C6: level_2_full_code | D6: =IFERROR(VLOOKUP($C6,'_METADATA_TEMPLATE'!$B$2:$H$826,2,FALSE),"") | E6: =IFERROR(VLOOKUP($C6,'_METADATA_TEMPLATE'!$B$2:$H$826,4,FALSE),"") | F6: =IFERROR(VLOOKUP($C6,'_METADATA_TEMPLATE'!$B$2:$H$826,5,FALSE),"") | G6: =IFERROR(VLOOKUP($C6,'_METADATA_TEMPLATE'!$B$2:$H$826,6,FALSE),"") | H6: =IFERROR(VLOOKUP($C6,'_METADATA_TEMPLATE'!$B$2:$H$826,7,FALSE),"") | I6: =IFERROR(VLOOKUP(C6,'_METADATA_DEFAULT'!$A:$B,2,FALSE),"") -> Kode Lengkap Kabupaten/Kota
A7: tgr_fd68e454.base_table_assignment_history | B7: assignment_id_date_created | C7: assignment_id_date_created | D7: =IFERROR(VLOOKUP($C7,'_METADATA_TEMPLATE'!$B$2:$H$826,2,FALSE),"") | E7: =IFERROR(VLOOKUP($C7,'_METADATA_TEMPLATE'!$B$2:$H$826,4,FALSE),"") | F7: =IFERROR(VLOOKUP($C7,'_METADATA_TEMPLATE'!$B$2:$H$826,5,FALSE),"") | G7: =IFERROR(VLOOKUP($C7,'_METADATA_TEMPLATE'!$B$2:$H$826,6,FALSE),"") | H7: =IFERROR(VLOOKUP($C7,'_METADATA_TEMPLATE'!$B$2:$H$826,7,FALSE),"") | I7: =IFERROR(VLOOKUP(C7,'_METADATA_DEFAULT'!$A:$B,2,FALSE),"")
A8: tgr_fd68e454.base_table_assignment_history | B8: assignment_id_timestamp | C8: assignment_id_timestamp | D8: =IFERROR(VLOOKUP($C8,'_METADATA_TEMPLATE'!$B$2:$H$826,2,FALSE),"") | E8: =IFERROR(VLOOKUP($C8,'_METADATA_TEMPLATE'!$B$2:$H$826,4,FALSE),"") | F8: =IFERROR(VLOOKUP($C8,'_METADATA_TEMPLATE'!$B$2:$H$826,5,FALSE),"") | G8: =IFERROR(VLOOKUP($C8,'_METADATA_TEMPLATE'!$B$2:$H$826,6,FALSE),"") | H8: =IFERROR(VLOOKUP($C8,'_METADATA_TEMPLATE'!$B$2:$H$826,7,FALSE),"") | I8: =IFERROR(VLOOKUP(C8,'_METADATA_DEFAULT'!$A:$B,2,FALSE),"") -> ID Assignment + Timestamp
A9: tgr_fd68e454.base_table_assignment_history | B9: remark | C9: remark | D9: =IFERROR(VLOOKUP($C9,'_METADATA_TEMPLATE'!$B$2:$H$826,2,FALSE),"") | E9: =IFERROR(VLOOKUP($C9,'_METADATA_TEMPLATE'!$B$2:$H$826,4,FALSE),"") | F9: =IFERROR(VLOOKUP($C9,'_METADATA_TEMPLATE'!$B$2:$H$826,5,FALSE),"") | G9: =IFERROR(VLOOKUP($C9,'_METADATA_TEMPLATE'!$B$2:$H$826,6,FALSE),"") | H9: =IFERROR(VLOOKUP($C9,'_METADATA_TEMPLATE'!$B$2:$H$826,7,FALSE),"") | I9: =IFERROR(VLOOKUP(C9,'_METADATA_DEFAULT'!$A:$B,2,FALSE),"")
A10: tgr_fd68e454.base_table_assignment_history | B10: user_id | C10: user_id | D10: =IFERROR(VLOOKUP($C10,'_METADATA_TEMPLATE'!$B$2:$H$826,2,FALSE),"") | E10: =IFERROR(VLOOKUP($C10,'_METADATA_TEMPLATE'!$B$2:$H$826,4,FALSE),"") | F10: =IFERROR(VLOOKUP($C10,'_METADATA_TEMPLATE'!$B$2:$H$826,5,FALSE),"") | G10: =IFERROR(VLOOKUP($C10,'_METADATA_TEMPLATE'!$B$2:$H$826,6,FALSE),"") | H10: =IFERROR(VLOOKUP($C10,'_METADATA_TEMPLATE'!$B$2:$H$826,7,FALSE),"") | I10: =IFERROR(VLOOKUP(C10,'_METADATA_DEFAULT'!$A:$B,2,FALSE),"")
A11: tgr_fd68e454.base_table_assignment_history | B11: status_id | C11: status_id | D11: =IFERROR(VLOOKUP($C11,'_METADATA_TEMPLATE'!$B$2:$H$826,2,FALSE),"") | E11: =IFERROR(VLOOKUP($C11,'_METADATA_TEMPLATE'!$B$2:$H$826,4,FALSE),"") | F11: =IFERROR(VLOOKUP($C11,'_METADATA_TEMPLATE'!$B$2:$H$826,5,FALSE),"") | G11: =IFERROR(VLOOKUP($C11,'_METADATA_TEMPLATE'!$B$2:$H$826,6,FALSE),"") | H11: =IFERROR(VLOOKUP($C11,'_METADATA_TEMPLATE'!$B$2:$H$826,7,FALSE),"") | I11: =IFERROR(VLOOKUP(C11,'_METADATA_DEFAULT'!$A:$B,2,FALSE),"")
A12: tgr_fd68e454.base_table_assignment_history | B12: status_alias | C12: status_alias | D12: =IFERROR(VLOOKUP($C12,'_METADATA_TEMPLATE'!$B$2:$H$826,2,FALSE),"") | E12: =IFERROR(VLOOKUP($C12,'_METADATA_TEMPLATE'!$B$2:$H$826,4,FALSE),"") | F12: =IFERROR(VLOOKUP($C12,'_METADATA_TEMPLATE'!$B$2:$H$826,5,FALSE),"") | G12: =IFERROR(VLOOKUP($C12,'_METADATA_TEMPLATE'!$B$2:$H$826,6,FALSE),"") | H12: =IFERROR(VLOOKUP($C12,'_METADATA_TEMPLATE'!$B$2:$H$826,7,FALSE),"") | I12: =IFERROR(VLOOKUP(C12,'_METADATA_DEFAULT'!$A:$B,2,FALSE),"")
A13: tgr_fd68e454.base_table_assignment_history | B13: assignment_date_modified | C13: assignment_date_modified | D13: =IFERROR(VLOOKUP($C13,'_METADATA_TEMPLATE'!$B$2:$H$826,2,FALSE),"") | E13: =IFERROR(VLOOKUP($C13,'_METADATA_TEMPLATE'!$B$2:$H$826,4,FALSE),"") | F13: =IFERROR(VLOOKUP($C13,'_METADATA_TEMPLATE'!$B$2:$H$826,5,FALSE),"") | G13: =IFERROR(VLOOKUP($C13,'_METADATA_TEMPLATE'!$B$2:$H$826,6,FALSE),"") | H13: =IFERROR(VLOOKUP($C13,'_METADATA_TEMPLATE'!$B$2:$H$826,7,FALSE),"") | I13: =IFERROR(VLOOKUP(C13,'_METADATA_DEFAULT'!$A:$B,2,FALSE),"") -> Tanggal Assignment Terakhir Diubah

Sheet tgr_fd68e454.base_table_assig_2
A1: Tabel | B1: Kolom | C1: DataKey | D1: Urutan | E1: Blok | F1: Nomor Rincian | G1: Label | H1: Tipe | I1: Keterangan
A2: tgr_fd68e454.base_table_assignment_responsibility | B2: assignment_id | C2: assignment_id | D2: =IFERROR(VLOOKUP($C2,'_METADATA_TEMPLATE'!$B$2:$H$826,2,FALSE),"") | E2: =IFERROR(VLOOKUP($C2,'_METADATA_TEMPLATE'!$B$2:$H$826,4,FALSE),"") | F2: =IFERROR(VLOOKUP($C2,'_METADATA_TEMPLATE'!$B$2:$H$826,5,FALSE),"") | G2: =IFERROR(VLOOKUP($C2,'_METADATA_TEMPLATE'!$B$2:$H$826,6,FALSE),"") | H2: =IFERROR(VLOOKUP($C2,'_METADATA_TEMPLATE'!$B$2:$H$826,7,FALSE),"") | I2: =IFERROR(VLOOKUP(C2,'_METADATA_DEFAULT'!$A:$B,2,FALSE),"") -> ID Assignment
A3: tgr_fd68e454.base_table_assignment_responsibility | B3: id | C3: id | D3: =IFERROR(VLOOKUP($C3,'_METADATA_TEMPLATE'!$B$2:$H$826,2,FALSE),"") | E3: =IFERROR(VLOOKUP($C3,'_METADATA_TEMPLATE'!$B$2:$H$826,4,FALSE),"") | F3: =IFERROR(VLOOKUP($C3,'_METADATA_TEMPLATE'!$B$2:$H$826,5,FALSE),"") | G3: =IFERROR(VLOOKUP($C3,'_METADATA_TEMPLATE'!$B$2:$H$826,6,FALSE),"") | H3: =IFERROR(VLOOKUP($C3,'_METADATA_TEMPLATE'!$B$2:$H$826,7,FALSE),"") | I3: =IFERROR(VLOOKUP(C3,'_METADATA_DEFAULT'!$A:$B,2,FALSE),"")
A4: tgr_fd68e454.base_table_assignment_responsibility | B4: level_1_full_code | C4: level_1_full_code | D4: =IFERROR(VLOOKUP($C4,'_METADATA_TEMPLATE'!$B$2:$H$826,2,FALSE),"") | E4: =IFERROR(VLOOKUP($C4,'_METADATA_TEMPLATE'!$B$2:$H$826,4,FALSE),"") | F4: =IFERROR(VLOOKUP($C4,'_METADATA_TEMPLATE'!$B$2:$H$826,5,FALSE),"") | G4: =IFERROR(VLOOKUP($C4,'_METADATA_TEMPLATE'!$B$2:$H$826,6,FALSE),"") | H4: =IFERROR(VLOOKUP($C4,'_METADATA_TEMPLATE'!$B$2:$H$826,7,FALSE),"") | I4: =IFERROR(VLOOKUP(C4,'_METADATA_DEFAULT'!$A:$B,2,FALSE),"") -> Kode Lengkap Provinsi
A5: tgr_fd68e454.base_table_assignment_responsibility | B5: level_2_full_code | C5: level_2_full_code | D5: =IFERROR(VLOOKUP($C5,'_METADATA_TEMPLATE'!$B$2:$H$826,2,FALSE),"") | E5: =IFERROR(VLOOKUP($C5,'_METADATA_TEMPLATE'!$B$2:$H$826,4,FALSE),"") | F5: =IFERROR(VLOOKUP($C5,'_METADATA_TEMPLATE'!$B$2:$H$826,5,FALSE),"") | G5: =IFERROR(VLOOKUP($C5,'_METADATA_TEMPLATE'!$B$2:$H$826,6,FALSE),"") | H5: =IFERROR(VLOOKUP($C5,'_METADATA_TEMPLATE'!$B$2:$H$826,7,FALSE),"") | I5: =IFERROR(VLOOKUP(C5,'_METADATA_DEFAULT'!$A:$B,2,FALSE),"") -> Kode Lengkap Kabupaten/Kota
A6: tgr_fd68e454.base_table_assignment_responsibility | B6: assignment_id_timestamp | C6: assignment_id_timestamp | D6: =IFERROR(VLOOKUP($C6,'_METADATA_TEMPLATE'!$B$2:$H$826,2,FALSE),"") | E6: =IFERROR(VLOOKUP($C6,'_METADATA_TEMPLATE'!$B$2:$H$826,4,FALSE),"") | F6: =IFERROR(VLOOKUP($C6,'_METADATA_TEMPLATE'!$B$2:$H$826,5,FALSE),"") | G6: =IFERROR(VLOOKUP($C6,'_METADATA_TEMPLATE'!$B$2:$H$826,6,FALSE),"") | H6: =IFERROR(VLOOKUP($C6,'_METADATA_TEMPLATE'!$B$2:$H$826,7,FALSE),"") | I6: =IFERROR(VLOOKUP(C6,'_METADATA_DEFAULT'!$A:$B,2,FALSE),"") -> ID Assignment + Timestamp
A7: tgr_fd68e454.base_table_assignment_responsibility | B7: survey_user_before_id | C7: survey_user_before_id | D7: =IFERROR(VLOOKUP($C7,'_METADATA_TEMPLATE'!$B$2:$H$826,2,FALSE),"") | E7: =IFERROR(VLOOKUP($C7,'_METADATA_TEMPLATE'!$B$2:$H$826,4,FALSE),"") | F7: =IFERROR(VLOOKUP($C7,'_METADATA_TEMPLATE'!$B$2:$H$826,5,FALSE),"") | G7: =IFERROR(VLOOKUP($C7,'_METADATA_TEMPLATE'!$B$2:$H$826,6,FALSE),"") | H7: =IFERROR(VLOOKUP($C7,'_METADATA_TEMPLATE'!$B$2:$H$826,7,FALSE),"") | I7: =IFERROR(VLOOKUP(C7,'_METADATA_DEFAULT'!$A:$B,2,FALSE),"")
A8: tgr_fd68e454.base_table_assignment_responsibility | B8: survey_user_current_id | C8: survey_user_current_id | D8: =IFERROR(VLOOKUP($C8,'_METADATA_TEMPLATE'!$B$2:$H$826,2,FALSE),"") | E8: =IFERROR(VLOOKUP($C8,'_METADATA_TEMPLATE'!$B$2:$H$826,4,FALSE),"") | F8: =IFERROR(VLOOKUP($C8,'_METADATA_TEMPLATE'!$B$2:$H$826,5,FALSE),"") | G8: =IFERROR(VLOOKUP($C8,'_METADATA_TEMPLATE'!$B$2:$H$826,6,FALSE),"") | H8: =IFERROR(VLOOKUP($C8,'_METADATA_TEMPLATE'!$B$2:$H$826,7,FALSE),"") | I8: =IFERROR(VLOOKUP(C8,'_METADATA_DEFAULT'!$A:$B,2,FALSE),"")
A9: tgr_fd68e454.base_table_assignment_responsibility | B9: assignment_responsibility_status_id | C9: assignment_responsibility_status_id | D9: =IFERROR(VLOOKUP($C9,'_METADATA_TEMPLATE'!$B$2:$H$826,2,FALSE),"") | E9: =IFERROR(VLOOKUP($C9,'_METADATA_TEMPLATE'!$B$2:$H$826,4,FALSE),"") | F9: =IFERROR(VLOOKUP($C9,'_METADATA_TEMPLATE'!$B$2:$H$826,5,FALSE),"") | G9: =IFERROR(VLOOKUP($C9,'_METADATA_TEMPLATE'!$B$2:$H$826,6,FALSE),"") | H9: =IFERROR(VLOOKUP($C9,'_METADATA_TEMPLATE'!$B$2:$H$826,7,FALSE),"") | I9: =IFERROR(VLOOKUP(C9,'_METADATA_DEFAULT'!$A:$B,2,FALSE),"")
A10: tgr_fd68e454.base_table_assignment_responsibility | B10: date_created | C10: date_created | D10: =IFERROR(VLOOKUP($C10,'_METADATA_TEMPLATE'!$B$2:$H$826,2,FALSE),"") | E10: =IFERROR(VLOOKUP($C10,'_METADATA_TEMPLATE'!$B$2:$H$826,4,FALSE),"") | F10: =IFERROR(VLOOKUP($C10,'_METADATA_TEMPLATE'!$B$2:$H$826,5,FALSE),"") | G10: =IFERROR(VLOOKUP($C10,'_METADATA_TEMPLATE'!$B$2:$H$826,6,FALSE),"") | H10: =IFERROR(VLOOKUP($C10,'_METADATA_TEMPLATE'!$B$2:$H$826,7,FALSE),"") | I10: =IFERROR(VLOOKUP(C10,'_METADATA_DEFAULT'!$A:$B,2,FALSE),"")
A11: tgr_fd68e454.base_table_assignment_responsibility | B11: is_active | C11: is_active | D11: =IFERROR(VLOOKUP($C11,'_METADATA_TEMPLATE'!$B$2:$H$826,2,FALSE),"") | E11: =IFERROR(VLOOKUP($C11,'_METADATA_TEMPLATE'!$B$2:$H$826,4,FALSE),"") | F11: =IFERROR(VLOOKUP($C11,'_METADATA_TEMPLATE'!$B$2:$H$826,5,FALSE),"") | G11: =IFERROR(VLOOKUP($C11,'_METADATA_TEMPLATE'!$B$2:$H$826,6,FALSE),"") | H11: =IFERROR(VLOOKUP($C11,'_METADATA_TEMPLATE'!$B$2:$H$826,7,FALSE),"") | I11: =IFERROR(VLOOKUP(C11,'_METADATA_DEFAULT'!$A:$B,2,FALSE),"") -> 1 = Aktif, 0 = Dihapus
A12: tgr_fd68e454.base_table_assignment_responsibility | B12: before_user_id | C12: before_user_id | D12: =IFERROR(VLOOKUP($C12,'_METADATA_TEMPLATE'!$B$2:$H$826,2,FALSE),"") | E12: =IFERROR(VLOOKUP($C12,'_METADATA_TEMPLATE'!$B$2:$H$826,4,FALSE),"") | F12: =IFERROR(VLOOKUP($C12,'_METADATA_TEMPLATE'!$B$2:$H$826,5,FALSE),"") | G12: =IFERROR(VLOOKUP($C12,'_METADATA_TEMPLATE'!$B$2:$H$826,6,FALSE),"") | H12: =IFERROR(VLOOKUP($C12,'_METADATA_TEMPLATE'!$B$2:$H$826,7,FALSE),"") | I12: =IFERROR(VLOOKUP(C12,'_METADATA_DEFAULT'!$A:$B,2,FALSE),"")
A13: tgr_fd68e454.base_table_assignment_responsibility | B13: before_survey_role_id | C13: before_survey_role_id | D13: =IFERROR(VLOOKUP($C13,'_METADATA_TEMPLATE'!$B$2:$H$826,2,FALSE),"") | E13: =IFERROR(VLOOKUP($C13,'_METADATA_TEMPLATE'!$B$2:$H$826,4,FALSE),"") | F13: =IFERROR(VLOOKUP($C13,'_METADATA_TEMPLATE'!$B$2:$H$826,5,FALSE),"") | G13: =IFERROR(VLOOKUP($C13,'_METADATA_TEMPLATE'!$B$2:$H$826,6,FALSE),"") | H13: =IFERROR(VLOOKUP($C13,'_METADATA_TEMPLATE'!$B$2:$H$826,7,FALSE),"") | I13: =IFERROR(VLOOKUP(C13,'_METADATA_DEFAULT'!$A:$B,2,FALSE),"")
... A27: tgr_fd68e454.base_table_assignment_responsibility | B27: assignment_date_modified | C27: assignment_date_modified | D27: =IFERROR(VLOOKUP($C27,'_METADATA_TEMPLATE'!$B$2:$H$826,2,FALSE),"") | E27: =IFERROR(VLOOKUP($C27,'_METADATA_TEMPLATE'!$B$2:$H$826,4,FALSE),"") | F27: =IFERROR(VLOOKUP($C27,'_METADATA_TEMPLATE'!$B$2:$H$826,5,FALSE),"") | G27: =IFERROR(VLOOKUP($C27,'_METADATA_TEMPLATE'!$B$2:$H$826,6,FALSE),"") | H27: =IFERROR(VLOOKUP($C27,'_METADATA_TEMPLATE'!$B$2:$H$826,7,FALSE),"") | I27: =IFERROR(VLOOKUP(C27,'_METADATA_DEFAULT'!$A:$B,2,FALSE),"") -> Tanggal Assignment Terakhir Diubah

Sheet tgr_fd68e454.base_table_paradat
A1: Tabel | B1: Kolom | C1: DataKey | D1: Urutan | E1: Blok | F1: Nomor Rincian | G1: Label | H1: Tipe | I1: Keterangan
A2: tgr_fd68e454.base_table_paradata_action_log | B2: assignment_id | C2: assignment_id | D2: =IFERROR(VLOOKUP($C2,'_METADATA_TEMPLATE'!$B$2:$H$826,2,FALSE),"") | E2: =IFERROR(VLOOKUP($C2,'_METADATA_TEMPLATE'!$B$2:$H$826,4,FALSE),"") | F2: =IFERROR(VLOOKUP($C2,'_METADATA_TEMPLATE'!$B$2:$H$826,5,FALSE),"") | G2: =IFERROR(VLOOKUP($C2,'_METADATA_TEMPLATE'!$B$2:$H$826,6,FALSE),"") | H2: =IFERROR(VLOOKUP($C2,'_METADATA_TEMPLATE'!$B$2:$H$826,7,FALSE),"") | I2: =IFERROR(VLOOKUP(C2,'_METADATA_DEFAULT'!$A:$B,2,FALSE),"") -> ID Assignment
A3: tgr_fd68e454.base_table_paradata_action_log | B3: timestamp | C3: timestamp | D3: =IFERROR(VLOOKUP($C3,'_METADATA_TEMPLATE'!$B$2:$H$826,2,FALSE),"") | E3: =IFERROR(VLOOKUP($C3,'_METADATA_TEMPLATE'!$B$2:$H$826,4,FALSE),"") | F3: =IFERROR(VLOOKUP($C3,'_METADATA_TEMPLATE'!$B$2:$H$826,5,FALSE),"") | G3: =IFERROR(VLOOKUP($C3,'_METADATA_TEMPLATE'!$B$2:$H$826,6,FALSE),"") | H3: =IFERROR(VLOOKUP($C3,'_METADATA_TEMPLATE'!$B$2:$H$826,7,FALSE),"") | I3: =IFERROR(VLOOKUP(C3,'_METADATA_DEFAULT'!$A:$B,2,FALSE),"")
A4: tgr_fd68e454.base_table_paradata_action_log | B4: level_1_full_code | C4: level_1_full_code | D4: =IFERROR(VLOOKUP($C4,'_METADATA_TEMPLATE'!$B$2:$H$826,2,FALSE),"") | E4: =IFERROR(VLOOKUP($C4,'_METADATA_TEMPLATE'!$B$2:$H$826,4,FALSE),"") | F4: =IFERROR(VLOOKUP($C4,'_METADATA_TEMPLATE'!$B$2:$H$826,5,FALSE),"") | G4: =IFERROR(VLOOKUP($C4,'_METADATA_TEMPLATE'!$B$2:$H$826,6,FALSE),"") | H4: =IFERROR(VLOOKUP($C4,'_METADATA_TEMPLATE'!$B$2:$H$826,7,FALSE),"") | I4: =IFERROR(VLOOKUP(C4,'_METADATA_DEFAULT'!$A:$B,2,FALSE),"") -> Kode Lengkap Provinsi
A5: tgr_fd68e454.base_table_paradata_action_log | B5: level_2_full_code | C5: level_2_full_code | D5: =IFERROR(VLOOKUP($C5,'_METADATA_TEMPLATE'!$B$2:$H$826,2,FALSE),"") | E5: =IFERROR(VLOOKUP($C5,'_METADATA_TEMPLATE'!$B$2:$H$826,4,FALSE),"") | F5: =IFERROR(VLOOKUP($C5,'_METADATA_TEMPLATE'!$B$2:$H$826,5,FALSE),"") | G5: =IFERROR(VLOOKUP($C5,'_METADATA_TEMPLATE'!$B$2:$H$826,6,FALSE),"") | H5: =IFERROR(VLOOKUP($C5,'_METADATA_TEMPLATE'!$B$2:$H$826,7,FALSE),"") | I5: =IFERROR(VLOOKUP(C5,'_METADATA_DEFAULT'!$A:$B,2,FALSE),"") -> Kode Lengkap Kabupaten/Kota
A6: tgr_fd68e454.base_table_paradata_action_log | B6: assignment_id_timestamp | C6: assignment_id_timestamp | D6: =IFERROR(VLOOKUP($C6,'_METADATA_TEMPLATE'!$B$2:$H$826,2,FALSE),"") | E6: =IFERROR(VLOOKUP($C6,'_METADATA_TEMPLATE'!$B$2:$H$826,4,FALSE),"") | F6: =IFERROR(VLOOKUP($C6,'_METADATA_TEMPLATE'!$B$2:$H$826,5,FALSE),"") | G6: =IFERROR(VLOOKUP($C6,'_METADATA_TEMPLATE'!$B$2:$H$826,6,FALSE),"") | H6: =IFERROR(VLOOKUP($C6,'_METADATA_TEMPLATE'!$B$2:$H$826,7,FALSE),"") | I6: =IFERROR(VLOOKUP(C6,'_METADATA_DEFAULT'!$A:$B,2,FALSE),"") -> ID Assignment + Timestamp
A7: tgr_fd68e454.base_table_paradata_action_log | B7: action | C7: action | D7: =IFERROR(VLOOKUP($C7,'_METADATA_TEMPLATE'!$B$2:$H$826,2,FALSE),"") | E7: =IFERROR(VLOOKUP($C7,'_METADATA_TEMPLATE'!$B$2:$H$826,4,FALSE),"") | F7: =IFERROR(VLOOKUP($C7,'_METADATA_TEMPLATE'!$B$2:$H$826,5,FALSE),"") | G7: =IFERROR(VLOOKUP($C7,'_METADATA_TEMPLATE'!$B$2:$H$826,6,FALSE),"") | H7: =IFERROR(VLOOKUP($C7,'_METADATA_TEMPLATE'!$B$2:$H$826,7,FALSE),"") | I7: =IFERROR(VLOOKUP(C7,'_METADATA_DEFAULT'!$A:$B,2,FALSE),"")
A8: tgr_fd68e454.base_table_paradata_action_log | B8: action_log_index | C8: action_log_index | D8: =IFERROR(VLOOKUP($C8,'_METADATA_TEMPLATE'!$B$2:$H$826,2,FALSE),"") | E8: =IFERROR(VLOOKUP($C8,'_METADATA_TEMPLATE'!$B$2:$H$826,4,FALSE),"") | F8: =IFERROR(VLOOKUP($C8,'_METADATA_TEMPLATE'!$B$2:$H$826,5,FALSE),"") | G8: =IFERROR(VLOOKUP($C8,'_METADATA_TEMPLATE'!$B$2:$H$826,6,FALSE),"") | H8: =IFERROR(VLOOKUP($C8,'_METADATA_TEMPLATE'!$B$2:$H$826,7,FALSE),"") | I8: =IFERROR(VLOOKUP(C8,'_METADATA_DEFAULT'!$A:$B,2,FALSE),"")
A9: tgr_fd68e454.base_table_paradata_action_log | B9: battery_info_battery_level | C9: battery_info_battery_level | D9: =IFERROR(VLOOKUP($C9,'_METADATA_TEMPLATE'!$B$2:$H$826,2,FALSE),"") | E9: =IFERROR(VLOOKUP($C9,'_METADATA_TEMPLATE'!$B$2:$H$826,4,FALSE),"") | F9: =IFERROR(VLOOKUP($C9,'_METADATA_TEMPLATE'!$B$2:$H$826,5,FALSE),"") | G9: =IFERROR(VLOOKUP($C9,'_METADATA_TEMPLATE'!$B$2:$H$826,6,FALSE),"") | H9: =IFERROR(VLOOKUP($C9,'_METADATA_TEMPLATE'!$B$2:$H$826,7,FALSE),"") | I9: =IFERROR(VLOOKUP(C9,'_METADATA_DEFAULT'!$A:$B,2,FALSE),"")
A10: tgr_fd68e454.base_table_paradata_action_log | B10: battery_info_battery_temperature | C10: battery_info_battery_temperature | D10: =IFERROR(VLOOKUP($C10,'_METADATA_TEMPLATE'!$B$2:$H$826,2,FALSE),"") | E10: =IFERROR(VLOOKUP($C10,'_METADATA_TEMPLATE'!$B$2:$H$826,4,FALSE),"") | F10: =IFERROR(VLOOKUP($C10,'_METADATA_TEMPLATE'!$B$2:$H$826,5,FALSE),"") | G10: =IFERROR(VLOOKUP($C10,'_METADATA_TEMPLATE'!$B$2:$H$826,6,FALSE),"") | H10: =IFERROR(VLOOKUP($C10,'_METADATA_TEMPLATE'!$B$2:$H$826,7,FALSE),"") | I10: =IFERROR(VLOOKUP(C10,'_METADATA_DEFAULT'!$A:$B,2,FALSE),"")
A11: tgr_fd68e454.base_table_paradata_action_log | B11: is_mock | C11: is_mock | D11: =IFERROR(VLOOKUP($C11,'_METADATA_TEMPLATE'!$B$2:$H$826,2,FALSE),"") | E11: =IFERROR(VLOOKUP($C11,'_METADATA_TEMPLATE'!$B$2:$H$826,4,FALSE),"") | F11: =IFERROR(VLOOKUP($C11,'_METADATA_TEMPLATE'!$B$2:$H$826,5,FALSE),"") | G11: =IFERROR(VLOOKUP($C11,'_METADATA_TEMPLATE'!$B$2:$H$826,6,FALSE),"") | H11: =IFERROR(VLOOKUP($C11,'_METADATA_TEMPLATE'!$B$2:$H$826,7,FALSE),"") | I11: =IFERROR(VLOOKUP(C11,'_METADATA_DEFAULT'!$A:$B,2,FALSE),"")
A12: tgr_fd68e454.base_table_paradata_action_log | B12: latitude | C12: latitude | D12: =IFERROR(VLOOKUP($C12,'_METADATA_TEMPLATE'!$B$2:$H$826,2,FALSE),"") | E12: =IFERROR(VLOOKUP($C12,'_METADATA_TEMPLATE'!$B$2:$H$826,4,FALSE),"") | F12: =IFERROR(VLOOKUP($C12,'_METADATA_TEMPLATE'!$B$2:$H$826,5,FALSE),"") | G12: =IFERROR(VLOOKUP($C12,'_METADATA_TEMPLATE'!$B$2:$H$826,6,FALSE),"") | H12: =IFERROR(VLOOKUP($C12,'_METADATA_TEMPLATE'!$B$2:$H$826,7,FALSE),"") | I12: =IFERROR(VLOOKUP(C12,'_METADATA_DEFAULT'!$A:$B,2,FALSE),"")
A13: tgr_fd68e454.base_table_paradata_action_log | B13: longitude | C13: longitude | D13: =IFERROR(VLOOKUP($C13,'_METADATA_TEMPLATE'!$B$2:$H$826,2,FALSE),"") | E13: =IFERROR(VLOOKUP($C13,'_METADATA_TEMPLATE'!$B$2:$H$826,4,FALSE),"") | F13: =IFERROR(VLOOKUP($C13,'_METADATA_TEMPLATE'!$B$2:$H$826,5,FALSE),"") | G13: =IFERROR(VLOOKUP($C13,'_METADATA_TEMPLATE'!$B$2:$H$826,6,FALSE),"") | H13: =IFERROR(VLOOKUP($C13,'_METADATA_TEMPLATE'!$B$2:$H$826,7,FALSE),"") | I13: =IFERROR(VLOOKUP(C13,'_METADATA_DEFAULT'!$A:$B,2,FALSE),"")
... A16: tgr_fd68e454.base_table_paradata_action_log | B16: assignment_date_modified | C16: assignment_date_modified | D16: =IFERROR(VLOOKUP($C16,'_METADATA_TEMPLATE'!$B$2:$H$826,2,FALSE),"") | E16: =IFERROR(VLOOKUP($C16,'_METADATA_TEMPLATE'!$B$2:$H$826,4,FALSE),"") | F16: =IFERROR(VLOOKUP($C16,'_METADATA_TEMPLATE'!$B$2:$H$826,5,FALSE),"") | G16: =IFERROR(VLOOKUP($C16,'_METADATA_TEMPLATE'!$B$2:$H$826,6,FALSE),"") | H16: =IFERROR(VLOOKUP($C16,'_METADATA_TEMPLATE'!$B$2:$H$826,7,FALSE),"") | I16: =IFERROR(VLOOKUP(C16,'_METADATA_DEFAULT'!$A:$B,2,FALSE),"") -> Tanggal Assignment Terakhir Diubah

Sheet tgr_fd68e454.base_table_user_al
A1: Tabel | B1: Kolom | C1: DataKey | D1: Urutan | E1: Blok | F1: Nomor Rincian | G1: Label | H1: Tipe | I1: Keterangan
A2: tgr_fd68e454.base_table_user_allocation | B2: email | C2: email | D2: =IFERROR(VLOOKUP($C2,'_METADATA_TEMPLATE'!$B$2:$H$826,2,FALSE),"") -> 131 | E2: =IFERROR(VLOOKUP($C2,'_METADATA_TEMPLATE'!$B$2:$H$826,4,FALSE),"") -> SE2026 - L BLOK II | F2: =IFERROR(VLOOKUP($C2,'_METADATA_TEMPLATE'!$B$2:$H$826,5,FALSE),"") | G2: =IFERROR(VLOOKUP($C2,'_METADATA_TEMPLATE'!$B$2:$H$826,6,FALSE),"") -> • Email | H2: =IFERROR(VLOOKUP($C2,'_METADATA_TEMPLATE'!$B$2:$H$826,7,FALSE),"") -> Text Input | I2: =IFERROR(VLOOKUP(C2,'_METADATA_DEFAULT'!$A:$B,2,FALSE),"")
A3: tgr_fd68e454.base_table_user_allocation | B3: id | C3: id | D3: =IFERROR(VLOOKUP($C3,'_METADATA_TEMPLATE'!$B$2:$H$826,2,FALSE),"") | E3: =IFERROR(VLOOKUP($C3,'_METADATA_TEMPLATE'!$B$2:$H$826,4,FALSE),"") | F3: =IFERROR(VLOOKUP($C3,'_METADATA_TEMPLATE'!$B$2:$H$826,5,FALSE),"") | G3: =IFERROR(VLOOKUP($C3,'_METADATA_TEMPLATE'!$B$2:$H$826,6,FALSE),"") | H3: =IFERROR(VLOOKUP($C3,'_METADATA_TEMPLATE'!$B$2:$H$826,7,FALSE),"") | I3: =IFERROR(VLOOKUP(C3,'_METADATA_DEFAULT'!$A:$B,2,FALSE),"")
A4: tgr_fd68e454.base_table_user_allocation | B4: allocation_id | C4: allocation_id | D4: =IFERROR(VLOOKUP($C4,'_METADATA_TEMPLATE'!$B$2:$H$826,2,FALSE),"") | E4: =IFERROR(VLOOKUP($C4,'_METADATA_TEMPLATE'!$B$2:$H$826,4,FALSE),"") | F4: =IFERROR(VLOOKUP($C4,'_METADATA_TEMPLATE'!$B$2:$H$826,5,FALSE),"") | G4: =IFERROR(VLOOKUP($C4,'_METADATA_TEMPLATE'!$B$2:$H$826,6,FALSE),"") | H4: =IFERROR(VLOOKUP($C4,'_METADATA_TEMPLATE'!$B$2:$H$826,7,FALSE),"") | I4: =IFERROR(VLOOKUP(C4,'_METADATA_DEFAULT'!$A:$B,2,FALSE),"")
A5: tgr_fd68e454.base_table_user_allocation | B5: assignment_id_timestamp | C5: assignment_id_timestamp | D5: =IFERROR(VLOOKUP($C5,'_METADATA_TEMPLATE'!$B$2:$H$826,2,FALSE),"") | E5: =IFERROR(VLOOKUP($C5,'_METADATA_TEMPLATE'!$B$2:$H$826,4,FALSE),"") | F5: =IFERROR(VLOOKUP($C5,'_METADATA_TEMPLATE'!$B$2:$H$826,5,FALSE),"") | G5: =IFERROR(VLOOKUP($C5,'_METADATA_TEMPLATE'!$B$2:$H$826,6,FALSE),"") | H5: =IFERROR(VLOOKUP($C5,'_METADATA_TEMPLATE'!$B$2:$H$826,7,FALSE),"") | I5: =IFERROR(VLOOKUP(C5,'_METADATA_DEFAULT'!$A:$B,2,FALSE),"") -> ID Assignment + Timestamp
A6: tgr_fd68e454.base_table_user_allocation | B6: blocks | C6: blocks | D6: =IFERROR(VLOOKUP($C6,'_METADATA_TEMPLATE'!$B$2:$H$826,2,FALSE),"") | E6: =IFERROR(VLOOKUP($C6,'_METADATA_TEMPLATE'!$B$2:$H$826,4,FALSE),"") | F6: =IFERROR(VLOOKUP($C6,'_METADATA_TEMPLATE'!$B$2:$H$826,5,FALSE),"") | G6: =IFERROR(VLOOKUP($C6,'_METADATA_TEMPLATE'!$B$2:$H$826,6,FALSE),"") | H6: =IFERROR(VLOOKUP($C6,'_METADATA_TEMPLATE'!$B$2:$H$826,7,FALSE),"") | I6: =IFERROR(VLOOKUP(C6,'_METADATA_DEFAULT'!$A:$B,2,FALSE),"")
A7: tgr_fd68e454.base_table_user_allocation | B7: fullname | C7: fullname | D7: =IFERROR(VLOOKUP($C7,'_METADATA_TEMPLATE'!$B$2:$H$826,2,FALSE),"") | E7: =IFERROR(VLOOKUP($C7,'_METADATA_TEMPLATE'!$B$2:$H$826,4,FALSE),"") | F7: =IFERROR(VLOOKUP($C7,'_METADATA_TEMPLATE'!$B$2:$H$826,5,FALSE),"") | G7: =IFERROR(VLOOKUP($C7,'_METADATA_TEMPLATE'!$B$2:$H$826,6,FALSE),"") | H7: =IFERROR(VLOOKUP($C7,'_METADATA_TEMPLATE'!$B$2:$H$826,7,FALSE),"") | I7: =IFERROR(VLOOKUP(C7,'_METADATA_DEFAULT'!$A:$B,2,FALSE),"")
A8: tgr_fd68e454.base_table_user_allocation | B8: region_id | C8: region_id | D8: =IFERROR(VLOOKUP($C8,'_METADATA_TEMPLATE'!$B$2:$H$826,2,FALSE),"") | E8: =IFERROR(VLOOKUP($C8,'_METADATA_TEMPLATE'!$B$2:$H$826,4,FALSE),"") | F8: =IFERROR(VLOOKUP($C8,'_METADATA_TEMPLATE'!$B$2:$H$826,5,FALSE),"") | G8: =IFERROR(VLOOKUP($C8,'_METADATA_TEMPLATE'!$B$2:$H$826,6,FALSE),"") | H8: =IFERROR(VLOOKUP($C8,'_METADATA_TEMPLATE'!$B$2:$H$826,7,FALSE),"") | I8: =IFERROR(VLOOKUP(C8,'_METADATA_DEFAULT'!$A:$B,2,FALSE),"")
A9: tgr_fd68e454.base_table_user_allocation | B9: role_sequence | C9: role_sequence | D9: =IFERROR(VLOOKUP($C9,'_METADATA_TEMPLATE'!$B$2:$H$826,2,FALSE),"") | E9: =IFERROR(VLOOKUP($C9,'_METADATA_TEMPLATE'!$B$2:$H$826,4,FALSE),"") | F9: =IFERROR(VLOOKUP($C9,'_METADATA_TEMPLATE'!$B$2:$H$826,5,FALSE),"") | G9: =IFERROR(VLOOKUP($C9,'_METADATA_TEMPLATE'!$B$2:$H$826,6,FALSE),"") | H9: =IFERROR(VLOOKUP($C9,'_METADATA_TEMPLATE'!$B$2:$H$826,7,FALSE),"") | I9: =IFERROR(VLOOKUP(C9,'_METADATA_DEFAULT'!$A:$B,2,FALSE),"")
A10: tgr_fd68e454.base_table_user_allocation | B10: role_description | C10: role_description | D10: =IFERROR(VLOOKUP($C10,'_METADATA_TEMPLATE'!$B$2:$H$826,2,FALSE),"") | E10: =IFERROR(VLOOKUP($C10,'_METADATA_TEMPLATE'!$B$2:$H$826,4,FALSE),"") | F10: =IFERROR(VLOOKUP($C10,'_METADATA_TEMPLATE'!$B$2:$H$826,5,FALSE),"") | G10: =IFERROR(VLOOKUP($C10,'_METADATA_TEMPLATE'!$B$2:$H$826,6,FALSE),"") | H10: =IFERROR(VLOOKUP($C10,'_METADATA_TEMPLATE'!$B$2:$H$826,7,FALSE),"") | I10: =IFERROR(VLOOKUP(C10,'_METADATA_DEFAULT'!$A:$B,2,FALSE),"")
A11: tgr_fd68e454.base_table_user_allocation | B11: survey_role_id | C11: survey_role_id | D11: =IFERROR(VLOOKUP($C11,'_METADATA_TEMPLATE'!$B$2:$H$826,2,FALSE),"") | E11: =IFERROR(VLOOKUP($C11,'_METADATA_TEMPLATE'!$B$2:$H$826,4,FALSE),"") | F11: =IFERROR(VLOOKUP($C11,'_METADATA_TEMPLATE'!$B$2:$H$826,5,FALSE),"") | G11: =IFERROR(VLOOKUP($C11,'_METADATA_TEMPLATE'!$B$2:$H$826,6,FALSE),"") | H11: =IFERROR(VLOOKUP($C11,'_METADATA_TEMPLATE'!$B$2:$H$826,7,FALSE),"") | I11: =IFERROR(VLOOKUP(C11,'_METADATA_DEFAULT'!$A:$B,2,FALSE),"")
A12: tgr_fd68e454.base_table_user_allocation | B12: survey_period_id | C12: survey_period_id | D12: =IFERROR(VLOOKUP($C12,'_METADATA_TEMPLATE'!$B$2:$H$826,2,FALSE),"") | E12: =IFERROR(VLOOKUP($C12,'_METADATA_TEMPLATE'!$B$2:$H$826,4,FALSE),"") | F12: =IFERROR(VLOOKUP($C12,'_METADATA_TEMPLATE'!$B$2:$H$826,5,FALSE),"") | G12: =IFERROR(VLOOKUP($C12,'_METADATA_TEMPLATE'!$B$2:$H$826,6,FALSE),"") | H12: =IFERROR(VLOOKUP($C12,'_METADATA_TEMPLATE'!$B$2:$H$826,7,FALSE),"") | I12: =IFERROR(VLOOKUP(C12,'_METADATA_DEFAULT'!$A:$B,2,FALSE),"") -> ID Periode Survei
A13: tgr_fd68e454.base_table_user_allocation | B13: survey_role_group_id | C13: survey_role_group_id | D13: =IFERROR(VLOOKUP($C13,'_METADATA_TEMPLATE'!$B$2:$H$826,2,FALSE),"") | E13: =IFERROR(VLOOKUP($C13,'_METADATA_TEMPLATE'!$B$2:$H$826,4,FALSE),"") | F13: =IFERROR(VLOOKUP($C13,'_METADATA_TEMPLATE'!$B$2:$H$826,5,FALSE),"") | G13: =IFERROR(VLOOKUP($C13,'_METADATA_TEMPLATE'!$B$2:$H$826,6,FALSE),"") | H13: =IFERROR(VLOOKUP($C13,'_METADATA_TEMPLATE'!$B$2:$H$826,7,FALSE),"") | I13: =IFERROR(VLOOKUP(C13,'_METADATA_DEFAULT'!$A:$B,2,FALSE),"")
... A20: tgr_fd68e454.base_table_user_allocation | B20: updated_at | C20: updated_at | D20: =IFERROR(VLOOKUP($C20,'_METADATA_TEMPLATE'!$B$2:$H$826,2,FALSE),"") | E20: =IFERROR(VLOOKUP($C20,'_METADATA_TEMPLATE'!$B$2:$H$826,4,FALSE),"") | F20: =IFERROR(VLOOKUP($C20,'_METADATA_TEMPLATE'!$B$2:$H$826,5,FALSE),"") | G20: =IFERROR(VLOOKUP($C20,'_METADATA_TEMPLATE'!$B$2:$H$826,6,FALSE),"") | H20: =IFERROR(VLOOKUP($C20,'_METADATA_TEMPLATE'!$B$2:$H$826,7,FALSE),"") | I20: =IFERROR(VLOOKUP(C20,'_METADATA_DEFAULT'!$A:$B,2,FALSE),"")

Sheet tgr_fd68e454.base_table_user__1
A1: Tabel | B1: Kolom | C1: DataKey | D1: Urutan | E1: Blok | F1: Nomor Rincian | G1: Label | H1: Tipe | I1: Keterangan
A2: tgr_fd68e454.base_table_user_allocation_new | B2: email | C2: email | D2: =IFERROR(VLOOKUP($C2,'_METADATA_TEMPLATE'!$B$2:$H$826,2,FALSE),"") -> 131 | E2: =IFERROR(VLOOKUP($C2,'_METADATA_TEMPLATE'!$B$2:$H$826,4,FALSE),"") -> SE2026 - L BLOK II | F2: =IFERROR(VLOOKUP($C2,'_METADATA_TEMPLATE'!$B$2:$H$826,5,FALSE),"") | G2: =IFERROR(VLOOKUP($C2,'_METADATA_TEMPLATE'!$B$2:$H$826,6,FALSE),"") -> • Email | H2: =IFERROR(VLOOKUP($C2,'_METADATA_TEMPLATE'!$B$2:$H$826,7,FALSE),"") -> Text Input | I2: =IFERROR(VLOOKUP(C2,'_METADATA_DEFAULT'!$A:$B,2,FALSE),"")
A3: tgr_fd68e454.base_table_user_allocation_new | B3: level_1_full_code | C3: level_1_full_code | D3: =IFERROR(VLOOKUP($C3,'_METADATA_TEMPLATE'!$B$2:$H$826,2,FALSE),"") | E3: =IFERROR(VLOOKUP($C3,'_METADATA_TEMPLATE'!$B$2:$H$826,4,FALSE),"") | F3: =IFERROR(VLOOKUP($C3,'_METADATA_TEMPLATE'!$B$2:$H$826,5,FALSE),"") | G3: =IFERROR(VLOOKUP($C3,'_METADATA_TEMPLATE'!$B$2:$H$826,6,FALSE),"") | H3: =IFERROR(VLOOKUP($C3,'_METADATA_TEMPLATE'!$B$2:$H$826,7,FALSE),"") | I3: =IFERROR(VLOOKUP(C3,'_METADATA_DEFAULT'!$A:$B,2,FALSE),"") -> Kode Lengkap Provinsi
A4: tgr_fd68e454.base_table_user_allocation_new | B4: level_2_full_code | C4: level_2_full_code | D4: =IFERROR(VLOOKUP($C4,'_METADATA_TEMPLATE'!$B$2:$H$826,2,FALSE),"") | E4: =IFERROR(VLOOKUP($C4,'_METADATA_TEMPLATE'!$B$2:$H$826,4,FALSE),"") | F4: =IFERROR(VLOOKUP($C4,'_METADATA_TEMPLATE'!$B$2:$H$826,5,FALSE),"") | G4: =IFERROR(VLOOKUP($C4,'_METADATA_TEMPLATE'!$B$2:$H$826,6,FALSE),"") | H4: =IFERROR(VLOOKUP($C4,'_METADATA_TEMPLATE'!$B$2:$H$826,7,FALSE),"") | I4: =IFERROR(VLOOKUP(C4,'_METADATA_DEFAULT'!$A:$B,2,FALSE),"") -> Kode Lengkap Kabupaten/Kota
A5: tgr_fd68e454.base_table_user_allocation_new | B5: user_id | C5: user_id | D5: =IFERROR(VLOOKUP($C5,'_METADATA_TEMPLATE'!$B$2:$H$826,2,FALSE),"") | E5: =IFERROR(VLOOKUP($C5,'_METADATA_TEMPLATE'!$B$2:$H$826,4,FALSE),"") | F5: =IFERROR(VLOOKUP($C5,'_METADATA_TEMPLATE'!$B$2:$H$826,5,FALSE),"") | G5: =IFERROR(VLOOKUP($C5,'_METADATA_TEMPLATE'!$B$2:$H$826,6,FALSE),"") | H5: =IFERROR(VLOOKUP($C5,'_METADATA_TEMPLATE'!$B$2:$H$826,7,FALSE),"") | I5: =IFERROR(VLOOKUP(C5,'_METADATA_DEFAULT'!$A:$B,2,FALSE),"")
A6: tgr_fd68e454.base_table_user_allocation_new | B6: region_id | C6: region_id | D6: =IFERROR(VLOOKUP($C6,'_METADATA_TEMPLATE'!$B$2:$H$826,2,FALSE),"") | E6: =IFERROR(VLOOKUP($C6,'_METADATA_TEMPLATE'!$B$2:$H$826,4,FALSE),"") | F6: =IFERROR(VLOOKUP($C6,'_METADATA_TEMPLATE'!$B$2:$H$826,5,FALSE),"") | G6: =IFERROR(VLOOKUP($C6,'_METADATA_TEMPLATE'!$B$2:$H$826,6,FALSE),"") | H6: =IFERROR(VLOOKUP($C6,'_METADATA_TEMPLATE'!$B$2:$H$826,7,FALSE),"") | I6: =IFERROR(VLOOKUP(C6,'_METADATA_DEFAULT'!$A:$B,2,FALSE),"")

Sheet tgr_fd68e454.kp_nested
A1: Tabel | B1: Kolom | C1: DataKey | D1: Urutan | E1: Blok | F1: Nomor Rincian | G1: Label | H1: Tipe | I1: Keterangan
A2: tgr_fd68e454.kp_nested | B2: kp_unit | C2: kp_unit | D2: =IFERROR(VLOOKUP($C2,'_METADATA_TEMPLATE'!$B$2:$H$826,2,FALSE),"") -> 100 | E2: =IFERROR(VLOOKUP($C2,'_METADATA_TEMPLATE'!$B$2:$H$826,4,FALSE),"") -> SE2026 - L BLOK II | F2: =IFERROR(VLOOKUP($C2,'_METADATA_TEMPLATE'!$B$2:$H$826,5,FALSE),"") | G2: =IFERROR(VLOOKUP($C2,'_METADATA_TEMPLATE'!$B$2:$H$826,6,FALSE),"") -> Nama Kantor/ Unit | H2: =IFERROR(VLOOKUP($C2,'_METADATA_TEMPLATE'!$B$2:$H$826,7,FALSE),"") -> Text Input | I2: =IFERROR(VLOOKUP(C2,'_METADATA_DEFAULT'!$A:$B,2,FALSE),"")
A3: tgr_fd68e454.kp_nested | B3: kp_jenis_label | C3: kp_jenis | D3: =IFERROR(VLOOKUP($C3,'_METADATA_TEMPLATE'!$B$2:$H$826,2,FALSE),"") -> 101 | E3: =IFERROR(VLOOKUP($C3,'_METADATA_TEMPLATE'!$B$2:$H$826,4,FALSE),"") -> SE2026 - L BLOK II | F3: =IFERROR(VLOOKUP($C3,'_METADATA_TEMPLATE'!$B$2:$H$826,5,FALSE),"") | G3: =IFERROR(VLOOKUP($C3,'_METADATA_TEMPLATE'!$B$2:$H$826,6,FALSE),"") -> Jenis Unit | H3: =IFERROR(VLOOKUP($C3,'_METADATA_TEMPLATE'!$B$2:$H$826,7,FALSE),"") -> Radio Group | I3: =IFERROR(VLOOKUP(C3,'_METADATA_DEFAULT'!$A:$B,2,FALSE),"")
A4: tgr_fd68e454.kp_nested | B4: kp_jenis_value | C4: kp_jenis | D4: =IFERROR(VLOOKUP($C4,'_METADATA_TEMPLATE'!$B$2:$H$826,2,FALSE),"") -> 101 | E4: =IFERROR(VLOOKUP($C4,'_METADATA_TEMPLATE'!$B$2:$H$826,4,FALSE),"") -> SE2026 - L BLOK II | F4: =IFERROR(VLOOKUP($C4,'_METADATA_TEMPLATE'!$B$2:$H$826,5,FALSE),"") | G4: =IFERROR(VLOOKUP($C4,'_METADATA_TEMPLATE'!$B$2:$H$826,6,FALSE),"") -> Jenis Unit | H4: =IFERROR(VLOOKUP($C4,'_METADATA_TEMPLATE'!$B$2:$H$826,7,FALSE),"") -> Radio Group | I4: =IFERROR(VLOOKUP(C4,'_METADATA_DEFAULT'!$A:$B,2,FALSE),"")
A5: tgr_fd68e454.kp_nested | B5: kp_prov_label | C5: kp_prov | D5: =IFERROR(VLOOKUP($C5,'_METADATA_TEMPLATE'!$B$2:$H$826,2,FALSE),"") -> 102 | E5: =IFERROR(VLOOKUP($C5,'_METADATA_TEMPLATE'!$B$2:$H$826,4,FALSE),"") -> SE2026 - L BLOK II | F5: =IFERROR(VLOOKUP($C5,'_METADATA_TEMPLATE'!$B$2:$H$826,5,FALSE),"") | G5: =IFERROR(VLOOKUP($C5,'_METADATA_TEMPLATE'!$B$2:$H$826,6,FALSE),"") -> Provinsi | H5: =IFERROR(VLOOKUP($C5,'_METADATA_TEMPLATE'!$B$2:$H$826,7,FALSE),"") -> Select | I5: =IFERROR(VLOOKUP(C5,'_METADATA_DEFAULT'!$A:$B,2,FALSE),"")
A6: tgr_fd68e454.kp_nested | B6: kp_prov_value | C6: kp_prov | D6: =IFERROR(VLOOKUP($C6,'_METADATA_TEMPLATE'!$B$2:$H$826,2,FALSE),"") -> 102 | E6: =IFERROR(VLOOKUP($C6,'_METADATA_TEMPLATE'!$B$2:$H$826,4,FALSE),"") -> SE2026 - L BLOK II | F6: =IFERROR(VLOOKUP($C6,'_METADATA_TEMPLATE'!$B$2:$H$826,5,FALSE),"") | G6: =IFERROR(VLOOKUP($C6,'_METADATA_TEMPLATE'!$B$2:$H$826,6,FALSE),"") -> Provinsi | H6: =IFERROR(VLOOKUP($C6,'_METADATA_TEMPLATE'!$B$2:$H$826,7,FALSE),"") -> Select | I6: =IFERROR(VLOOKUP(C6,'_METADATA_DEFAULT'!$A:$B,2,FALSE),"")
A7: tgr_fd68e454.kp_nested | B7: kp_kab_label | C7: kp_kab | D7: =IFERROR(VLOOKUP($C7,'_METADATA_TEMPLATE'!$B$2:$H$826,2,FALSE),"") -> 104 | E7: =IFERROR(VLOOKUP($C7,'_METADATA_TEMPLATE'!$B$2:$H$826,4,FALSE),"") -> SE2026 - L BLOK II | F7: =IFERROR(VLOOKUP($C7,'_METADATA_TEMPLATE'!$B$2:$H$826,5,FALSE),"") | G7: =IFERROR(VLOOKUP($C7,'_METADATA_TEMPLATE'!$B$2:$H$826,6,FALSE),"") -> Kabupaten | H7: =IFERROR(VLOOKUP($C7,'_METADATA_TEMPLATE'!$B$2:$H$826,7,FALSE),"") -> Select | I7: =IFERROR(VLOOKUP(C7,'_METADATA_DEFAULT'!$A:$B,2,FALSE),"")
A8: tgr_fd68e454.kp_nested | B8: kp_kab_value | C8: kp_kab | D8: =IFERROR(VLOOKUP($C8,'_METADATA_TEMPLATE'!$B$2:$H$826,2,FALSE),"") -> 104 | E8: =IFERROR(VLOOKUP($C8,'_METADATA_TEMPLATE'!$B$2:$H$826,4,FALSE),"") -> SE2026 - L BLOK II | F8: =IFERROR(VLOOKUP($C8,'_METADATA_TEMPLATE'!$B$2:$H$826,5,FALSE),"") | G8: =IFERROR(VLOOKUP($C8,'_METADATA_TEMPLATE'!$B$2:$H$826,6,FALSE),"") -> Kabupaten | H8: =IFERROR(VLOOKUP($C8,'_METADATA_TEMPLATE'!$B$2:$H$826,7,FALSE),"") -> Select | I8: =IFERROR(VLOOKUP(C8,'_METADATA_DEFAULT'!$A:$B,2,FALSE),"")
A9: tgr_fd68e454.kp_nested | B9: kp_produksi_lingkungan_label | C9: kp_produksi_lingkungan | D9: =IFERROR(VLOOKUP($C9,'_METADATA_TEMPLATE'!$B$2:$H$826,2,FALSE),"") -> 105 | E9: =IFERROR(VLOOKUP($C9,'_METADATA_TEMPLATE'!$B$2:$H$826,4,FALSE),"") -> SE2026 - L BLOK II | F9: =IFERROR(VLOOKUP($C9,'_METADATA_TEMPLATE'!$B$2:$H$826,5,FALSE),"") | G9: =IFERROR(VLOOKUP($C9,'_METADATA_TEMPLATE'!$B$2:$H$826,6,FALSE),"") -> Apakah perusahaan ini memproduksi barang/jasa yang ramah lingkungan? | H9: =IFERROR(VLOOKUP($C9,'_METADATA_TEMPLATE'!$B$2:$H$826,7,FALSE),"") -> Radio Group | I9: =IFERROR(VLOOKUP(C9,'_METADATA_DEFAULT'!$A:$B,2,FALSE),"")
A10: tgr_fd68e454.kp_nested | B10: kp_produksi_lingkungan_value | C10: kp_produksi_lingkungan | D10: =IFERROR(VLOOKUP($C10,'_METADATA_TEMPLATE'!$B$2:$H$826,2,FALSE),"") -> 105 | E10: =IFERROR(VLOOKUP($C10,'_METADATA_TEMPLATE'!$B$2:$H$826,4,FALSE),"") -> SE2026 - L BLOK II | F10: =IFERROR(VLOOKUP($C10,'_METADATA_TEMPLATE'!$B$2:$H$826,5,FALSE),"") | G10: =IFERROR(VLOOKUP($C10,'_METADATA_TEMPLATE'!$B$2:$H$826,6,FALSE),"") -> Apakah perusahaan ini memproduksi barang/jasa yang ramah lingkungan? | H10: =IFERROR(VLOOKUP($C10,'_METADATA_TEMPLATE'!$B$2:$H$826,7,FALSE),"") -> Radio Group | I10: =IFERROR(VLOOKUP(C10,'_METADATA_DEFAULT'!$A:$B,2,FALSE),"")
A11: tgr_fd68e454.kp_nested | B11: kp_perlindungan_lingkungan_label | C11: kp_perlindungan_lingkungan | D11: =IFERROR(VLOOKUP($C11,'_METADATA_TEMPLATE'!$B$2:$H$826,2,FALSE),"") -> 108 | E11: =IFERROR(VLOOKUP($C11,'_METADATA_TEMPLATE'!$B$2:$H$826,4,FALSE),"") -> SE2026 - L BLOK II | F11: =IFERROR(VLOOKUP($C11,'_METADATA_TEMPLATE'!$B$2:$H$826,5,FALSE),"") | G11: =IFERROR(VLOOKUP($C11,'_METADATA_TEMPLATE'!$B$2:$H$826,6,FALSE),"") -> Apakah perusahaan ini mengeluarkan biaya perlindungan lingkungan dan/atau pembelian barang dan jasa yang ramah lingkungan | H11: =IFERROR(VLOOKUP($C11,'_METADATA_TEMPLATE'!$B$2:$H$826,7,FALSE),"") -> Radio Group | I11: =IFERROR(VLOOKUP(C11,'_METADATA_DEFAULT'!$A:$B,2,FALSE),"")
A12: tgr_fd68e454.kp_nested | B12: kp_perlindungan_lingkungan_value | C12: kp_perlindungan_lingkungan | D12: =IFERROR(VLOOKUP($C12,'_METADATA_TEMPLATE'!$B$2:$H$826,2,FALSE),"") -> 108 | E12: =IFERROR(VLOOKUP($C12,'_METADATA_TEMPLATE'!$B$2:$H$826,4,FALSE),"") -> SE2026 - L BLOK II | F12: =IFERROR(VLOOKUP($C12,'_METADATA_TEMPLATE'!$B$2:$H$826,5,FALSE),"") | G12: =IFERROR(VLOOKUP($C12,'_METADATA_TEMPLATE'!$B$2:$H$826,6,FALSE),"") -> Apakah perusahaan ini mengeluarkan biaya perlindungan lingkungan dan/atau pembelian barang dan jasa yang ramah lingkungan | H12: =IFERROR(VLOOKUP($C12,'_METADATA_TEMPLATE'!$B$2:$H$826,7,FALSE),"") -> Radio Group | I12: =IFERROR(VLOOKUP(C12,'_METADATA_DEFAULT'!$A:$B,2,FALSE),"")
A13: tgr_fd68e454.kp_nested | B13: kp_tk | C13: kp_tk | D13: =IFERROR(VLOOKUP($C13,'_METADATA_TEMPLATE'!$B$2:$H$826,2,FALSE),"") -> 109 | E13: =IFERROR(VLOOKUP($C13,'_METADATA_TEMPLATE'!$B$2:$H$826,4,FALSE),"") -> SE2026 - L BLOK II | F13: =IFERROR(VLOOKUP($C13,'_METADATA_TEMPLATE'!$B$2:$H$826,5,FALSE),"") | G13: =IFERROR(VLOOKUP($C13,'_METADATA_TEMPLATE'!$B$2:$H$826,6,FALSE),"") -> Jumlah Pekerja (per 31 Desember 2025) (orang) | H13: =IFERROR(VLOOKUP($C13,'_METADATA_TEMPLATE'!$B$2:$H$826,7,FALSE),"") -> Number | I13: =IFERROR(VLOOKUP(C13,'_METADATA_DEFAULT'!$A:$B,2,FALSE),"")
... A57: tgr_fd68e454.kp_nested | B57: survey_period_name | C57: survey_period_name | D57: =IFERROR(VLOOKUP($C57,'_METADATA_TEMPLATE'!$B$2:$H$826,2,FALSE),"") | E57: =IFERROR(VLOOKUP($C57,'_METADATA_TEMPLATE'!$B$2:$H$826,4,FALSE),"") | F57: =IFERROR(VLOOKUP($C57,'_METADATA_TEMPLATE'!$B$2:$H$826,5,FALSE),"") | G57: =IFERROR(VLOOKUP($C57,'_METADATA_TEMPLATE'!$B$2:$H$826,6,FALSE),"") | H57: =IFERROR(VLOOKUP($C57,'_METADATA_TEMPLATE'!$B$2:$H$826,7,FALSE),"") | I57: =IFERROR(VLOOKUP(C57,'_METADATA_DEFAULT'!$A:$B,2,FALSE),"")

Sheet tgr_fd68e454.nested_dtsen
A1: Tabel | B1: Kolom | C1: DataKey | D1: Urutan | E1: Blok | F1: Nomor Rincian | G1: Label | H1: Tipe | I1: Keterangan
A2: tgr_fd68e454.nested_dtsen | B2: nama_dtsen | C2: nama_dtsen | D2: =IFERROR(VLOOKUP($C2,'_METADATA_TEMPLATE'!$B$2:$H$826,2,FALSE),"") -> 70 | E2: =IFERROR(VLOOKUP($C2,'_METADATA_TEMPLATE'!$B$2:$H$826,4,FALSE),"") -> SE2026 - L BLOK I | F2: =IFERROR(VLOOKUP($C2,'_METADATA_TEMPLATE'!$B$2:$H$826,5,FALSE),"") -> 6 | G2: =IFERROR(VLOOKUP($C2,'_METADATA_TEMPLATE'!$B$2:$H$826,6,FALSE),"") -> Nama anggota keluarga | H2: =IFERROR(VLOOKUP($C2,'_METADATA_TEMPLATE'!$B$2:$H$826,7,FALSE),"") -> Variable | I2: =IFERROR(VLOOKUP(C2,'_METADATA_DEFAULT'!$A:$B,2,FALSE),"")
A3: tgr_fd68e454.nested_dtsen | B3: nik_dtsen | C3: nik_dtsen | D3: =IFERROR(VLOOKUP($C3,'_METADATA_TEMPLATE'!$B$2:$H$826,2,FALSE),"") -> 72 | E3: =IFERROR(VLOOKUP($C3,'_METADATA_TEMPLATE'!$B$2:$H$826,4,FALSE),"") -> SE2026 - L BLOK I | F3: =IFERROR(VLOOKUP($C3,'_METADATA_TEMPLATE'!$B$2:$H$826,5,FALSE),"") -> 7 | G3: =IFERROR(VLOOKUP($C3,'_METADATA_TEMPLATE'!$B$2:$H$826,6,FALSE),"") -> Nomor Induk Kependudukan (NIK) $NAME$ (Tulis sesuai yang tercantum di KK atau KTP paling mutakhir) | H3: =IFERROR(VLOOKUP($C3,'_METADATA_TEMPLATE'!$B$2:$H$826,7,FALSE),"") -> Text Input | I3: =IFERROR(VLOOKUP(C3,'_METADATA_DEFAULT'!$A:$B,2,FALSE),"")
A4: tgr_fd68e454.nested_dtsen | B4: hubungan_label | C4: hubungan | D4: =IFERROR(VLOOKUP($C4,'_METADATA_TEMPLATE'!$B$2:$H$826,2,FALSE),"") -> 74 | E4: =IFERROR(VLOOKUP($C4,'_METADATA_TEMPLATE'!$B$2:$H$826,4,FALSE),"") -> SE2026 - L BLOK I | F4: =IFERROR(VLOOKUP($C4,'_METADATA_TEMPLATE'!$B$2:$H$826,5,FALSE),"") -> 8 | G4: =IFERROR(VLOOKUP($C4,'_METADATA_TEMPLATE'!$B$2:$H$826,6,FALSE),"") -> Hubungan $NAME$ dengan Kepala Keluarga | H4: =IFERROR(VLOOKUP($C4,'_METADATA_TEMPLATE'!$B$2:$H$826,7,FALSE),"") -> Radio Group | I4: =IFERROR(VLOOKUP(C4,'_METADATA_DEFAULT'!$A:$B,2,FALSE),"")
A5: tgr_fd68e454.nested_dtsen | B5: hubungan_value | C5: hubungan | D5: =IFERROR(VLOOKUP($C5,'_METADATA_TEMPLATE'!$B$2:$H$826,2,FALSE),"") -> 74 | E5: =IFERROR(VLOOKUP($C5,'_METADATA_TEMPLATE'!$B$2:$H$826,4,FALSE),"") -> SE2026 - L BLOK I | F5: =IFERROR(VLOOKUP($C5,'_METADATA_TEMPLATE'!$B$2:$H$826,5,FALSE),"") -> 8 | G5: =IFERROR(VLOOKUP($C5,'_METADATA_TEMPLATE'!$B$2:$H$826,6,FALSE),"") -> Hubungan $NAME$ dengan Kepala Keluarga | H5: =IFERROR(VLOOKUP($C5,'_METADATA_TEMPLATE'!$B$2:$H$826,7,FALSE),"") -> Radio Group | I5: =IFERROR(VLOOKUP(C5,'_METADATA_DEFAULT'!$A:$B,2,FALSE),"")
A6: tgr_fd68e454.nested_dtsen | B6: keberadaan_dtsen_label | C6: keberadaan_dtsen | D6: =IFERROR(VLOOKUP($C6,'_METADATA_TEMPLATE'!$B$2:$H$826,2,FALSE),"") -> 75 | E6: =IFERROR(VLOOKUP($C6,'_METADATA_TEMPLATE'!$B$2:$H$826,4,FALSE),"") -> SE2026 - L BLOK I | F6: =IFERROR(VLOOKUP($C6,'_METADATA_TEMPLATE'!$B$2:$H$826,5,FALSE),"") -> 9 | G6: =IFERROR(VLOOKUP($C6,'_METADATA_TEMPLATE'!$B$2:$H$826,6,FALSE),"") -> a. Keberadaan (status) anggota keluarga saat ini | H6: =IFERROR(VLOOKUP($C6,'_METADATA_TEMPLATE'!$B$2:$H$826,7,FALSE),"") -> Radio Group | I6: =IFERROR(VLOOKUP(C6,'_METADATA_DEFAULT'!$A:$B,2,FALSE),"")
A7: tgr_fd68e454.nested_dtsen | B7: keberadaan_dtsen_value | C7: keberadaan_dtsen | D7: =IFERROR(VLOOKUP($C7,'_METADATA_TEMPLATE'!$B$2:$H$826,2,FALSE),"") -> 75 | E7: =IFERROR(VLOOKUP($C7,'_METADATA_TEMPLATE'!$B$2:$H$826,4,FALSE),"") -> SE2026 - L BLOK I | F7: =IFERROR(VLOOKUP($C7,'_METADATA_TEMPLATE'!$B$2:$H$826,5,FALSE),"") -> 9 | G7: =IFERROR(VLOOKUP($C7,'_METADATA_TEMPLATE'!$B$2:$H$826,6,FALSE),"") -> a. Keberadaan (status) anggota keluarga saat ini | H7: =IFERROR(VLOOKUP($C7,'_METADATA_TEMPLATE'!$B$2:$H$826,7,FALSE),"") -> Radio Group | I7: =IFERROR(VLOOKUP(C7,'_METADATA_DEFAULT'!$A:$B,2,FALSE),"")
A8: tgr_fd68e454.nested_dtsen | B8: alamat_dn_label | C8: alamat_dn | D8: =IFERROR(VLOOKUP($C8,'_METADATA_TEMPLATE'!$B$2:$H$826,2,FALSE),"") -> 76 | E8: =IFERROR(VLOOKUP($C8,'_METADATA_TEMPLATE'!$B$2:$H$826,4,FALSE),"") -> SE2026 - L BLOK I | F8: =IFERROR(VLOOKUP($C8,'_METADATA_TEMPLATE'!$B$2:$H$826,5,FALSE),"") -> 9 | G8: =IFERROR(VLOOKUP($C8,'_METADATA_TEMPLATE'!$B$2:$H$826,6,FALSE),"") -> b. Alamat domisili: | H8: =IFERROR(VLOOKUP($C8,'_METADATA_TEMPLATE'!$B$2:$H$826,7,FALSE),"") -> Radio Group | I8: =IFERROR(VLOOKUP(C8,'_METADATA_DEFAULT'!$A:$B,2,FALSE),"")
A9: tgr_fd68e454.nested_dtsen | B9: alamat_dn_value | C9: alamat_dn | D9: =IFERROR(VLOOKUP($C9,'_METADATA_TEMPLATE'!$B$2:$H$826,2,FALSE),"") -> 76 | E9: =IFERROR(VLOOKUP($C9,'_METADATA_TEMPLATE'!$B$2:$H$826,4,FALSE),"") -> SE2026 - L BLOK I | F9: =IFERROR(VLOOKUP($C9,'_METADATA_TEMPLATE'!$B$2:$H$826,5,FALSE),"") -> 9 | G9: =IFERROR(VLOOKUP($C9,'_METADATA_TEMPLATE'!$B$2:$H$826,6,FALSE),"") -> b. Alamat domisili: | H9: =IFERROR(VLOOKUP($C9,'_METADATA_TEMPLATE'!$B$2:$H$826,7,FALSE),"") -> Radio Group | I9: =IFERROR(VLOOKUP(C9,'_METADATA_DEFAULT'!$A:$B,2,FALSE),"")
A10: tgr_fd68e454.nested_dtsen | B10: prov_dn_label | C10: prov_dn | D10: =IFERROR(VLOOKUP($C10,'_METADATA_TEMPLATE'!$B$2:$H$826,2,FALSE),"") -> 77 | E10: =IFERROR(VLOOKUP($C10,'_METADATA_TEMPLATE'!$B$2:$H$826,4,FALSE),"") -> SE2026 - L BLOK I | F10: =IFERROR(VLOOKUP($C10,'_METADATA_TEMPLATE'!$B$2:$H$826,5,FALSE),"") -> a | G10: =IFERROR(VLOOKUP($C10,'_METADATA_TEMPLATE'!$B$2:$H$826,6,FALSE),"") -> Provinsi | H10: =IFERROR(VLOOKUP($C10,'_METADATA_TEMPLATE'!$B$2:$H$826,7,FALSE),"") -> Select | I10: =IFERROR(VLOOKUP(C10,'_METADATA_DEFAULT'!$A:$B,2,FALSE),"")
A11: tgr_fd68e454.nested_dtsen | B11: prov_dn_value | C11: prov_dn | D11: =IFERROR(VLOOKUP($C11,'_METADATA_TEMPLATE'!$B$2:$H$826,2,FALSE),"") -> 77 | E11: =IFERROR(VLOOKUP($C11,'_METADATA_TEMPLATE'!$B$2:$H$826,4,FALSE),"") -> SE2026 - L BLOK I | F11: =IFERROR(VLOOKUP($C11,'_METADATA_TEMPLATE'!$B$2:$H$826,5,FALSE),"") -> a | G11: =IFERROR(VLOOKUP($C11,'_METADATA_TEMPLATE'!$B$2:$H$826,6,FALSE),"") -> Provinsi | H11: =IFERROR(VLOOKUP($C11,'_METADATA_TEMPLATE'!$B$2:$H$826,7,FALSE),"") -> Select | I11: =IFERROR(VLOOKUP(C11,'_METADATA_DEFAULT'!$A:$B,2,FALSE),"")
A12: tgr_fd68e454.nested_dtsen | B12: kab_dn_label | C12: kab_dn | D12: =IFERROR(VLOOKUP($C12,'_METADATA_TEMPLATE'!$B$2:$H$826,2,FALSE),"") -> 78 | E12: =IFERROR(VLOOKUP($C12,'_METADATA_TEMPLATE'!$B$2:$H$826,4,FALSE),"") -> SE2026 - L BLOK I | F12: =IFERROR(VLOOKUP($C12,'_METADATA_TEMPLATE'!$B$2:$H$826,5,FALSE),"") -> b | G12: =IFERROR(VLOOKUP($C12,'_METADATA_TEMPLATE'!$B$2:$H$826,6,FALSE),"") -> Kabupaten/Kota | H12: =IFERROR(VLOOKUP($C12,'_METADATA_TEMPLATE'!$B$2:$H$826,7,FALSE),"") -> Select | I12: =IFERROR(VLOOKUP(C12,'_METADATA_DEFAULT'!$A:$B,2,FALSE),"")
A13: tgr_fd68e454.nested_dtsen | B13: kab_dn_value | C13: kab_dn | D13: =IFERROR(VLOOKUP($C13,'_METADATA_TEMPLATE'!$B$2:$H$826,2,FALSE),"") -> 78 | E13: =IFERROR(VLOOKUP($C13,'_METADATA_TEMPLATE'!$B$2:$H$826,4,FALSE),"") -> SE2026 - L BLOK I | F13: =IFERROR(VLOOKUP($C13,'_METADATA_TEMPLATE'!$B$2:$H$826,5,FALSE),"") -> b | G13: =IFERROR(VLOOKUP($C13,'_METADATA_TEMPLATE'!$B$2:$H$826,6,FALSE),"") -> Kabupaten/Kota | H13: =IFERROR(VLOOKUP($C13,'_METADATA_TEMPLATE'!$B$2:$H$826,7,FALSE),"") -> Select | I13: =IFERROR(VLOOKUP(C13,'_METADATA_DEFAULT'!$A:$B,2,FALSE),"")
... A71: tgr_fd68e454.nested_dtsen | B71: survey_period_name | C71: survey_period_name | D71: =IFERROR(VLOOKUP($C71,'_METADATA_TEMPLATE'!$B$2:$H$826,2,FALSE),"") | E71: =IFERROR(VLOOKUP($C71,'_METADATA_TEMPLATE'!$B$2:$H$826,4,FALSE),"") | F71: =IFERROR(VLOOKUP($C71,'_METADATA_TEMPLATE'!$B$2:$H$826,5,FALSE),"") | G71: =IFERROR(VLOOKUP($C71,'_METADATA_TEMPLATE'!$B$2:$H$826,6,FALSE),"") | H71: =IFERROR(VLOOKUP($C71,'_METADATA_TEMPLATE'!$B$2:$H$826,7,FALSE),"") | I71: =IFERROR(VLOOKUP(C71,'_METADATA_DEFAULT'!$A:$B,2,FALSE),"")

Sheet tgr_fd68e454.nested_dtsen_var
A1: Tabel | B1: Kolom | C1: DataKey | D1: Urutan | E1: Blok | F1: Nomor Rincian | G1: Label | H1: Tipe | I1: Keterangan
A2: tgr_fd68e454.nested_dtsen_var | B2: no_urut_kk_var | C2: no_urut_kk_var | D2: =IFERROR(VLOOKUP($C2,'_METADATA_TEMPLATE'!$B$2:$H$826,2,FALSE),"") -> 270 | E2: =IFERROR(VLOOKUP($C2,'_METADATA_TEMPLATE'!$B$2:$H$826,4,FALSE),"") -> SE2026 - L BLOK III | F2: =IFERROR(VLOOKUP($C2,'_METADATA_TEMPLATE'!$B$2:$H$826,5,FALSE),"") | G2: =IFERROR(VLOOKUP($C2,'_METADATA_TEMPLATE'!$B$2:$H$826,6,FALSE),"") -> Nomor urut anggota keluarga | H2: =IFERROR(VLOOKUP($C2,'_METADATA_TEMPLATE'!$B$2:$H$826,7,FALSE),"") -> Variable | I2: =IFERROR(VLOOKUP(C2,'_METADATA_DEFAULT'!$A:$B,2,FALSE),"")
A3: tgr_fd68e454.nested_dtsen_var | B3: nama_dtsen_var | C3: nama_dtsen_var | D3: =IFERROR(VLOOKUP($C3,'_METADATA_TEMPLATE'!$B$2:$H$826,2,FALSE),"") -> 271 | E3: =IFERROR(VLOOKUP($C3,'_METADATA_TEMPLATE'!$B$2:$H$826,4,FALSE),"") -> SE2026 - L BLOK III | F3: =IFERROR(VLOOKUP($C3,'_METADATA_TEMPLATE'!$B$2:$H$826,5,FALSE),"") | G3: =IFERROR(VLOOKUP($C3,'_METADATA_TEMPLATE'!$B$2:$H$826,6,FALSE),"") -> Nama anggota keluarga | H3: =IFERROR(VLOOKUP($C3,'_METADATA_TEMPLATE'!$B$2:$H$826,7,FALSE),"") -> Variable | I3: =IFERROR(VLOOKUP(C3,'_METADATA_DEFAULT'!$A:$B,2,FALSE),"")
A4: tgr_fd68e454.nested_dtsen_var | B4: sekolah_label | C4: sekolah | D4: =IFERROR(VLOOKUP($C4,'_METADATA_TEMPLATE'!$B$2:$H$826,2,FALSE),"") -> 272 | E4: =IFERROR(VLOOKUP($C4,'_METADATA_TEMPLATE'!$B$2:$H$826,4,FALSE),"") -> SE2026 - L BLOK III | F4: =IFERROR(VLOOKUP($C4,'_METADATA_TEMPLATE'!$B$2:$H$826,5,FALSE),"") -> 14 | G4: =IFERROR(VLOOKUP($C4,'_METADATA_TEMPLATE'!$B$2:$H$826,6,FALSE),"") -> Partisipasi sekolah $NAME$ | H4: =IFERROR(VLOOKUP($C4,'_METADATA_TEMPLATE'!$B$2:$H$826,7,FALSE),"") -> Radio Group | I4: =IFERROR(VLOOKUP(C4,'_METADATA_DEFAULT'!$A:$B,2,FALSE),"")
A5: tgr_fd68e454.nested_dtsen_var | B5: sekolah_value | C5: sekolah | D5: =IFERROR(VLOOKUP($C5,'_METADATA_TEMPLATE'!$B$2:$H$826,2,FALSE),"") -> 272 | E5: =IFERROR(VLOOKUP($C5,'_METADATA_TEMPLATE'!$B$2:$H$826,4,FALSE),"") -> SE2026 - L BLOK III | F5: =IFERROR(VLOOKUP($C5,'_METADATA_TEMPLATE'!$B$2:$H$826,5,FALSE),"") -> 14 | G5: =IFERROR(VLOOKUP($C5,'_METADATA_TEMPLATE'!$B$2:$H$826,6,FALSE),"") -> Partisipasi sekolah $NAME$ | H5: =IFERROR(VLOOKUP($C5,'_METADATA_TEMPLATE'!$B$2:$H$826,7,FALSE),"") -> Radio Group | I5: =IFERROR(VLOOKUP(C5,'_METADATA_DEFAULT'!$A:$B,2,FALSE),"")
A6: tgr_fd68e454.nested_dtsen_var | B6: ijazah_label | C6: ijazah | D6: =IFERROR(VLOOKUP($C6,'_METADATA_TEMPLATE'!$B$2:$H$826,2,FALSE),"") -> 273 | E6: =IFERROR(VLOOKUP($C6,'_METADATA_TEMPLATE'!$B$2:$H$826,4,FALSE),"") -> SE2026 - L BLOK III | F6: =IFERROR(VLOOKUP($C6,'_METADATA_TEMPLATE'!$B$2:$H$826,5,FALSE),"") -> 15 | G6: =IFERROR(VLOOKUP($C6,'_METADATA_TEMPLATE'!$B$2:$H$826,6,FALSE),"") -> Ijazah/STTB tertinggi yang dimiliki $NAME$ (usia 5 tahun ke atas) Ijazah/STTB tertinggi di prelist: $ijazah | H6: =IFERROR(VLOOKUP($C6,'_METADATA_TEMPLATE'!$B$2:$H$826,7,FALSE),"") -> Radio Group | I6: =IFERROR(VLOOKUP(C6,'_METADATA_DEFAULT'!$A:$B,2,FALSE),"")
A7: tgr_fd68e454.nested_dtsen_var | B7: ijazah_value | C7: ijazah | D7: =IFERROR(VLOOKUP($C7,'_METADATA_TEMPLATE'!$B$2:$H$826,2,FALSE),"") -> 273 | E7: =IFERROR(VLOOKUP($C7,'_METADATA_TEMPLATE'!$B$2:$H$826,4,FALSE),"") -> SE2026 - L BLOK III | F7: =IFERROR(VLOOKUP($C7,'_METADATA_TEMPLATE'!$B$2:$H$826,5,FALSE),"") -> 15 | G7: =IFERROR(VLOOKUP($C7,'_METADATA_TEMPLATE'!$B$2:$H$826,6,FALSE),"") -> Ijazah/STTB tertinggi yang dimiliki $NAME$ (usia 5 tahun ke atas) Ijazah/STTB tertinggi di prelist: $ijazah | H7: =IFERROR(VLOOKUP($C7,'_METADATA_TEMPLATE'!$B$2:$H$826,7,FALSE),"") -> Radio Group | I7: =IFERROR(VLOOKUP(C7,'_METADATA_DEFAULT'!$A:$B,2,FALSE),"")
A8: tgr_fd68e454.nested_dtsen_var | B8: profesi_label | C8: profesi | D8: =IFERROR(VLOOKUP($C8,'_METADATA_TEMPLATE'!$B$2:$H$826,2,FALSE),"") -> 274 | E8: =IFERROR(VLOOKUP($C8,'_METADATA_TEMPLATE'!$B$2:$H$826,4,FALSE),"") -> SE2026 - L BLOK III | F8: =IFERROR(VLOOKUP($C8,'_METADATA_TEMPLATE'!$B$2:$H$826,5,FALSE),"") -> 16 | G8: =IFERROR(VLOOKUP($C8,'_METADATA_TEMPLATE'!$B$2:$H$826,6,FALSE),"") -> Profesi Pekerjaan Utama $NAME$ (usia 10 tahun ke atas) | H8: =IFERROR(VLOOKUP($C8,'_METADATA_TEMPLATE'!$B$2:$H$826,7,FALSE),"") -> Select | I8: =IFERROR(VLOOKUP(C8,'_METADATA_DEFAULT'!$A:$B,2,FALSE),"")
A9: tgr_fd68e454.nested_dtsen_var | B9: profesi_value | C9: profesi | D9: =IFERROR(VLOOKUP($C9,'_METADATA_TEMPLATE'!$B$2:$H$826,2,FALSE),"") -> 274 | E9: =IFERROR(VLOOKUP($C9,'_METADATA_TEMPLATE'!$B$2:$H$826,4,FALSE),"") -> SE2026 - L BLOK III | F9: =IFERROR(VLOOKUP($C9,'_METADATA_TEMPLATE'!$B$2:$H$826,5,FALSE),"") -> 16 | G9: =IFERROR(VLOOKUP($C9,'_METADATA_TEMPLATE'!$B$2:$H$826,6,FALSE),"") -> Profesi Pekerjaan Utama $NAME$ (usia 10 tahun ke atas) | H9: =IFERROR(VLOOKUP($C9,'_METADATA_TEMPLATE'!$B$2:$H$826,7,FALSE),"") -> Select | I9: =IFERROR(VLOOKUP(C9,'_METADATA_DEFAULT'!$A:$B,2,FALSE),"")
A10: tgr_fd68e454.nested_dtsen_var | B10: profesi_lainnya | C10: profesi_lainnya | D10: =IFERROR(VLOOKUP($C10,'_METADATA_TEMPLATE'!$B$2:$H$826,2,FALSE),"") -> 275 | E10: =IFERROR(VLOOKUP($C10,'_METADATA_TEMPLATE'!$B$2:$H$826,4,FALSE),"") -> SE2026 - L BLOK III | F10: =IFERROR(VLOOKUP($C10,'_METADATA_TEMPLATE'!$B$2:$H$826,5,FALSE),"") | G10: =IFERROR(VLOOKUP($C10,'_METADATA_TEMPLATE'!$B$2:$H$826,6,FALSE),"") -> Profesi Pekerjaan Utama lainnya: | H10: =IFERROR(VLOOKUP($C10,'_METADATA_TEMPLATE'!$B$2:$H$826,7,FALSE),"") -> Text Input | I10: =IFERROR(VLOOKUP(C10,'_METADATA_DEFAULT'!$A:$B,2,FALSE),"")
A11: tgr_fd68e454.nested_dtsen_var | B11: status_kerja_label | C11: status_kerja | D11: =IFERROR(VLOOKUP($C11,'_METADATA_TEMPLATE'!$B$2:$H$826,2,FALSE),"") -> 276 | E11: =IFERROR(VLOOKUP($C11,'_METADATA_TEMPLATE'!$B$2:$H$826,4,FALSE),"") -> SE2026 - L BLOK III | F11: =IFERROR(VLOOKUP($C11,'_METADATA_TEMPLATE'!$B$2:$H$826,5,FALSE),"") -> 17 | G11: =IFERROR(VLOOKUP($C11,'_METADATA_TEMPLATE'!$B$2:$H$826,6,FALSE),"") -> Status Kedudukan Dalam Pekerjaan Utama $NAME$ | H11: =IFERROR(VLOOKUP($C11,'_METADATA_TEMPLATE'!$B$2:$H$826,7,FALSE),"") -> Radio Group | I11: =IFERROR(VLOOKUP(C11,'_METADATA_DEFAULT'!$A:$B,2,FALSE),"")
